Workbook

Sheet Home
A1: INTERACTIVE BODY MAP DASHBOARD TUTORIAL
A3: This spreadsheet is for the Interactive Body Map Dashboard Tutorial hosted on https://adamvirgile.com/. All videos for this tutorial can be found via the link below: | F3: If you have any questions, please contact Adam Virgile:
G5: Email | H5: adam.virgile@gmail.com
A6: Tutorial link: | B6: Interactive Body Map Dashboard Tutorial | G6: Twitter | H6: @AdamVirgile

Sheet BodyMapData_1
A1: Athlete | B1: Date | C1: Head | D1: NeckFront | E1: NeckBack | F1: L_Shoulder | G1: L_ArmUpper | H1: L_Elbow | I1: L_ArmLower | J1: L_Wrist | K1: L_Hand | L1: R_Shoulder | M1: R_ArmUpper | N1: R_Elbow | O1: R_ArmLower | P1: R_Wrist | Q1: R_Hand | R1: L_Chest | S1: L_Abs | T1: L_Hip | U1: L_Quad | V1: L_Knee | W1: L_Shin | X1: L_Ankle | Y1: L_Foot | Z1: R_Chest | AA1: R_Abs | AB1: R_Hip | AC1: R_Quad | AD1: R_Knee | AE1: R_Shin | AF1: R_Ankle | AG1: R_Foot | AH1: L_BackUpper | AI1: L_BackLower | AJ1: L_Butt | AK1: L_Hamstring | AL1: L_Calf | AM1: R_BackUpper | AN1: R_BackLower | AO1: R_Butt | AP1: R_Hamstring | AQ1: R_Calf
A2: LeQuan James | B2: 43919
A3: LeQuan James | B3: 43920 | S3: 2 | T3: 4 | V3: 2 | W3: 3
A4: LeQuan James | B4: 43922 | E4: 4 | S4: 2 | T4: 2 | V4: 2 | W4: 4
A5: LeQuan James | B5: 43923 | S5: 1 | T5: 3 | V5: 2 | W5: 3
A6: LeQuan James | B6: 43924
A7: Mikal Jordan | B7: 43919 | H7: 4 | I7: 5 | AC7: 3
A8: Mikal Jordan | B8: 43920 | H8: 2 | I8: 4
A9: Mikal Jordan | B9: 43922 | I9: 1 | AC9: 3
A10: Mikal Jordan | B10: 43923 | I10: 1
A11: Mikal Jordan | B11: 43924 | I11: 1
A12: Harry Bird | B12: 43919 | C12: 4 | AQ12: 2
A13: Harry Bird | B13: 43920 | C13: 5 | AQ13: 2
A14: Harry Bird | B14: 43922 | C14: 1 | O14: 4 | AQ14: 3
A15: Harry Bird | B15: 43923 | AQ15: 3
A16: Harry Bird | B16: 43924 | AQ16: 1
A17: Ron Stockton | B17: 43919
A18: Ron Stockton | B18: 43920
A19: Ron Stockton | B19: 43922 | D19: 4 | H19: 1 | I19: 3 | K19: 1 | M19: 1 | N19: 4 | O19: 1 | P19: 3 | R19: 4 | S19: 5 | T19: 1 | U19: 3 | V19: 1 | W19: 1 | X19: 5 | Y19: 1 | AB19: 3 | AD19: 5 | AE19: 4 | AF19: 4 | AI19: 1 | AK19: 4 | AO19: 3
A20: Ron Stockton | B20: 43923
A21: Ron Stockton | B21: 43924 | C21: 1 | E21: 1 | T21: 1 | AK21: 4 | AQ21: 4
A22: Phil Brussel | B22: 43919
A23: Phil Brussel | B23: 43920
A24: Phil Brussel | B24: 43922 | E24: 3 | K24: 4 | P24: 3 | Q24: 3 | R24: 3 | S24: 3 | Z24: 4 | AQ24: 5
A25: Phil Brussel | B25: 43923 | L25: 3
A26: Phil Brussel | B26: 43924 | I26: 5 | U26: 4 | V26: 5 | X26: 5 | Y26: 1 | AC26: 3 | AE26: 3 | AF26: 1
A27: Karl Barkly | B27: 43919 | K27: 5 | AJ27: 3
A28: Karl Barkly | B28: 43920 | K28: 4 | AJ28: 2
A29: Karl Barkly | B29: 43922 | K29: 4 | AJ29: 3
A30: Karl Barkly | B30: 43923 | K30: 3 | AJ30: 1
A31: Karl Barkly | B31: 43924 | C31: 4 | D31: 4 | K31: 1 | AJ31: 1

Sheet BodyMapData_2
A1: Athlete | B1: Date | C1: Body Part | D1: Metric | E1: Value
A2: LeQuan James | B2: 43920 | C2: L_Abs | D2: Soreness | E2: 3
A3: LeQuan James | B3: 43920 | C3: L_Hip | D3: Soreness | E3: 2
A4: LeQuan James | B4: 43920 | C4: L_Knee | D4: Soreness | E4: 1
A5: LeQuan James | B5: 43921 | C5: L_Abs | D5: Soreness | E5: 5
A6: LeQuan James | B6: 43921 | C6: L_Hip | D6: Soreness | E6: 1
A7: LeQuan James | B7: 43921 | C7: L_Knee | D7: Soreness | E7: 1
A8: LeQuan James | B8: 43922 | C8: L_Abs | D8: Soreness | E8: 3
A9: LeQuan James | B9: 43922 | C9: L_Hip | D9: Soreness | E9: 1
A10: Mikal Jordan | B10: 43919 | C10: R_Elbow | D10: Soreness | E10: 7
A11: Mikal Jordan | B11: 43920 | C11: R_Elbow | D11: Soreness | E11: 6
A12: Mikal Jordan | B12: 43922 | C12: R_Elbow | D12: Soreness | E12: 4
A13: Mikal Jordan | B13: 43922 | C13: R_Wrist | D13: Soreness | E13: 3
... A41: Phil Brussel | B41: 43924 | C41: R_Knee | D41: Soreness | E41: 3

Sheet XYs_1
F2: Part | G2: X | H2: Y | I2: Athlete Value | J2: Athlete X | K2: Athlete Y
F3: {=TRANSPOSE(BodyMapData_1!C1:AQ1)} -> Head | G3: 21.5 | H3: 95 | I3: {=INDEX(BodyMapData_1!$A:$AQ,MATCH(1,(Dashboard_1!$B$3=BodyMapData_1!$A:$A)*(Dashboard_1!$B$4=BodyMapData_1!$B:$B),0),MATCH($F3,BodyMapData_1!$A$1:$AQ$1,0))} -> 1 | J3: =IF($I3="","",G3) -> 21.5 | K3: =IF($I3="","",H3) -> 95
F4: NeckFront | G4: 21.5 | H4: 83 | I4: {=INDEX(BodyMapData_1!$A:$AQ,MATCH(1,(Dashboard_1!$B$3=BodyMapData_1!$A:$A)*(Dashboard_1!$B$4=BodyMapData_1!$B:$B),0),MATCH($F4,BodyMapData_1!$A$1:$AQ$1,0))} | J4: =IF($I4="","",G4) | K4: =IF($I4="","",H4)
F5: NeckBack | G5: 72 | H5: 88 | I5: {=INDEX(BodyMapData_1!$A:$AQ,MATCH(1,(Dashboard_1!$B$3=BodyMapData_1!$A:$A)*(Dashboard_1!$B$4=BodyMapData_1!$B:$B),0),MATCH($F5,BodyMapData_1!$A$1:$AQ$1,0))} | J5: =IF($I5="","",G5) | K5: =IF($I5="","",H5)
F6: L_Shoulder | G6: 32 | H6: 80 | I6: {=INDEX(BodyMapData_1!$A:$AQ,MATCH(1,(Dashboard_1!$B$3=BodyMapData_1!$A:$A)*(Dashboard_1!$B$4=BodyMapData_1!$B:$B),0),MATCH($F6,BodyMapData_1!$A$1:$AQ$1,0))} | J6: =IF($I6="","",G6) | K6: =IF($I6="","",H6)
F7: L_ArmUpper | G7: 33 | H7: 72 | I7: {=INDEX(BodyMapData_1!$A:$AQ,MATCH(1,(Dashboard_1!$B$3=BodyMapData_1!$A:$A)*(Dashboard_1!$B$4=BodyMapData_1!$B:$B),0),MATCH($F7,BodyMapData_1!$A$1:$AQ$1,0))} | J7: =IF($I7="","",G7) | K7: =IF($I7="","",H7)
F8: L_Elbow | G8: 34 | H8: 65 | I8: {=INDEX(BodyMapData_1!$A:$AQ,MATCH(1,(Dashboard_1!$B$3=BodyMapData_1!$A:$A)*(Dashboard_1!$B$4=BodyMapData_1!$B:$B),0),MATCH($F8,BodyMapData_1!$A$1:$AQ$1,0))} | J8: =IF($I8="","",G8) | K8: =IF($I8="","",H8)
F9: L_ArmLower | G9: 36 | H9: 58 | I9: {=INDEX(BodyMapData_1!$A:$AQ,MATCH(1,(Dashboard_1!$B$3=BodyMapData_1!$A:$A)*(Dashboard_1!$B$4=BodyMapData_1!$B:$B),0),MATCH($F9,BodyMapData_1!$A$1:$AQ$1,0))} | J9: =IF($I9="","",G9) | K9: =IF($I9="","",H9)
F10: L_Wrist | G10: 88 | H10: 53 | I10: {=INDEX(BodyMapData_1!$A:$AQ,MATCH(1,(Dashboard_1!$B$3=BodyMapData_1!$A:$A)*(Dashboard_1!$B$4=BodyMapData_1!$B:$B),0),MATCH($F10,BodyMapData_1!$A$1:$AQ$1,0))} | J10: =IF($I10="","",G10) | K10: =IF($I10="","",H10)
F11: L_Hand | G11: 39 | H11: 49 | I11: {=INDEX(BodyMapData_1!$A:$AQ,MATCH(1,(Dashboard_1!$B$3=BodyMapData_1!$A:$A)*(Dashboard_1!$B$4=BodyMapData_1!$B:$B),0),MATCH($F11,BodyMapData_1!$A$1:$AQ$1,0))} | J11: =IF($I11="","",G11) | K11: =IF($I11="","",H11)
F12: R_Shoulder | G12: 11 | H12: 80 | I12: {=INDEX(BodyMapData_1!$A:$AQ,MATCH(1,(Dashboard_1!$B$3=BodyMapData_1!$A:$A)*(Dashboard_1!$B$4=BodyMapData_1!$B:$B),0),MATCH($F12,BodyMapData_1!$A$1:$AQ$1,0))} | J12: =IF($I12="","",G12) | K12: =IF($I12="","",H12)
F13: R_ArmUpper | G13: 10 | H13: 72 | I13: {=INDEX(BodyMapData_1!$A:$AQ,MATCH(1,(Dashboard_1!$B$3=BodyMapData_1!$A:$A)*(Dashboard_1!$B$4=BodyMapData_1!$B:$B),0),MATCH($F13,BodyMapData_1!$A$1:$AQ$1,0))} | J13: =IF($I13="","",G13) | K13: =IF($I13="","",H13)
F14: R_Elbow | G14: 9 | H14: 65 | I14: {=INDEX(BodyMapData_1!$A:$AQ,MATCH(1,(Dashboard_1!$B$3=BodyMapData_1!$A:$A)*(Dashboard_1!$B$4=BodyMapData_1!$B:$B),0),MATCH($F14,BodyMapData_1!$A$1:$AQ$1,0))} | J14: =IF($I14="","",G14) | K14: =IF($I14="","",H14)
F15: R_ArmLower | G15: 7 | H15: 58 | I15: {=INDEX(BodyMapData_1!$A:$AQ,MATCH(1,(Dashboard_1!$B$3=BodyMapData_1!$A:$A)*(Dashboard_1!$B$4=BodyMapData_1!$B:$B),0),MATCH($F15,BodyMapData_1!$A$1:$AQ$1,0))} -> 4 | J15: =IF($I15="","",G15) -> 7 | K15: =IF($I15="","",H15) -> 58
... F43: R_Calf | G43: 77 | H43: 18 | I43: {=INDEX(BodyMapData_1!$A:$AQ,MATCH(1,(Dashboard_1!$B$3=BodyMapData_1!$A:$A)*(Dashboard_1!$B$4=BodyMapData_1!$B:$B),0),MATCH($F43,BodyMapData_1!$A$1:$AQ$1,0))} -> 3 | J43: =IF($I43="","",G43) -> 77 | K43: =IF($I43="","",H43) -> 18

Sheet XYs_2
M1: Athlete Soreness Over Time
F2: Part | G2: X | H2: Y | I2: Athlete Value | J2: Athlete X | K2: Athlete Y | M2: Date | N2: Total Soreness | O2: Maximum Soreness
F3: {=TRANSPOSE(BodyMapData_1!C1:AQ1)} -> Head | G3: 21.5 | H3: 95 | I3: =IFERROR(AVERAGEIFS(BodyMapData_2!$E:$E,BodyMapData_2!$C:$C,$F3,BodyMapData_2!$B:$B,Dashboard_2!$C$4,BodyMapData_2!$A:$A,Dashboard_2!$C$3),"") -> 1 | J3: =IF($I3="","",G3) -> 21.5 | K3: =IF($I3="","",H3) -> 95 | M3: =IFERROR(__xludf.DUMMYFUNCTION("SORT(UNIQUE(FILTER(BodyMapData_2!B:B,BodyMapData_2!A:A=Dashboard_2!C3)))"),43919.0) -> 43919 | N3: =IF(SUMIFS(BodyMapData_2!$E:$E,BodyMapData_2!$A:$A,Dashboard_2!$C$3,BodyMapData_2!$B:$B,$M3)=0,"", SUMIFS(BodyMapData_2!$E:$E,BodyMapData_2!$A:$A,Dashboard_2!$C$3,BodyMapData_2!$B:$B,$M3)) -> 9 | O3: =IF(MAXIFS(BodyMapData_2!$E:$E,BodyMapData_2!$A:$A,Dashboard_2!$C$3,BodyMapData_2!$B:$B,$M3)=0,"", MAXIFS(BodyMapData_2!$E:$E,BodyMapData_2!$A:$A,Dashboard_2!$C$3,BodyMapData_2!$B:$B,$M3)) -> 6
F4: NeckFront | G4: 21.5 | H4: 83 | I4: =IFERROR(AVERAGEIFS(BodyMapData_2!$E:$E,BodyMapData_2!$C:$C,$F4,BodyMapData_2!$B:$B,Dashboard_2!$C$4,BodyMapData_2!$A:$A,Dashboard_2!$C$3),"") | J4: =IF($I4="","",G4) | K4: =IF($I4="","",H4) | M4: =IFERROR(__xludf.DUMMYFUNCTION("""COMPUTED_VALUE"""),43920.0) -> 43920 | N4: =IF(SUMIFS(BodyMapData_2!$E:$E,BodyMapData_2!$A:$A,Dashboard_2!$C$3,BodyMapData_2!$B:$B,$M4)=0,"", SUMIFS(BodyMapData_2!$E:$E,BodyMapData_2!$A:$A,Dashboard_2!$C$3,BodyMapData_2!$B:$B,$M4)) -> 6 | O4: =IF(MAXIFS(BodyMapData_2!$E:$E,BodyMapData_2!$A:$A,Dashboard_2!$C$3,BodyMapData_2!$B:$B,$M4)=0,"", MAXIFS(BodyMapData_2!$E:$E,BodyMapData_2!$A:$A,Dashboard_2!$C$3,BodyMapData_2!$B:$B,$M4)) -> 6
F5: NeckBack | G5: 72 | H5: 88 | I5: =IFERROR(AVERAGEIFS(BodyMapData_2!$E:$E,BodyMapData_2!$C:$C,$F5,BodyMapData_2!$B:$B,Dashboard_2!$C$4,BodyMapData_2!$A:$A,Dashboard_2!$C$3),"") | J5: =IF($I5="","",G5) | K5: =IF($I5="","",H5) | M5: =IFERROR(__xludf.DUMMYFUNCTION("""COMPUTED_VALUE"""),43921.0) -> 43921 | N5: =IF(SUMIFS(BodyMapData_2!$E:$E,BodyMapData_2!$A:$A,Dashboard_2!$C$3,BodyMapData_2!$B:$B,$M5)=0,"", SUMIFS(BodyMapData_2!$E:$E,BodyMapData_2!$A:$A,Dashboard_2!$C$3,BodyMapData_2!$B:$B,$M5)) -> 14 | O5: =IF(MAXIFS(BodyMapData_2!$E:$E,BodyMapData_2!$A:$A,Dashboard_2!$C$3,BodyMapData_2!$B:$B,$M5)=0,"", MAXIFS(BodyMapData_2!$E:$E,BodyMapData_2!$A:$A,Dashboard_2!$C$3,BodyMapData_2!$B:$B,$M5)) -> 7
F6: L_Shoulder | G6: 32 | H6: 80 | I6: =IFERROR(AVERAGEIFS(BodyMapData_2!$E:$E,BodyMapData_2!$C:$C,$F6,BodyMapData_2!$B:$B,Dashboard_2!$C$4,BodyMapData_2!$A:$A,Dashboard_2!$C$3),"") | J6: =IF($I6="","",G6) | K6: =IF($I6="","",H6) | M6: =IFERROR(__xludf.DUMMYFUNCTION("""COMPUTED_VALUE"""),43922.0) -> 43922 | N6: =IF(SUMIFS(BodyMapData_2!$E:$E,BodyMapData_2!$A:$A,Dashboard_2!$C$3,BodyMapData_2!$B:$B,$M6)=0,"", SUMIFS(BodyMapData_2!$E:$E,BodyMapData_2!$A:$A,Dashboard_2!$C$3,BodyMapData_2!$B:$B,$M6)) -> 7 | O6: =IF(MAXIFS(BodyMapData_2!$E:$E,BodyMapData_2!$A:$A,Dashboard_2!$C$3,BodyMapData_2!$B:$B,$M6)=0,"", MAXIFS(BodyMapData_2!$E:$E,BodyMapData_2!$A:$A,Dashboard_2!$C$3,BodyMapData_2!$B:$B,$M6)) -> 5
F7: L_ArmUpper | G7: 33 | H7: 72 | I7: =IFERROR(AVERAGEIFS(BodyMapData_2!$E:$E,BodyMapData_2!$C:$C,$F7,BodyMapData_2!$B:$B,Dashboard_2!$C$4,BodyMapData_2!$A:$A,Dashboard_2!$C$3),"") | J7: =IF($I7="","",G7) | K7: =IF($I7="","",H7) | N7: =IF(SUMIFS(BodyMapData_2!$E:$E,BodyMapData_2!$A:$A,Dashboard_2!$C$3,BodyMapData_2!$B:$B,$M7)=0,"", SUMIFS(BodyMapData_2!$E:$E,BodyMapData_2!$A:$A,Dashboard_2!$C$3,BodyMapData_2!$B:$B,$M7)) | O7: =IF(MAXIFS(BodyMapData_2!$E:$E,BodyMapData_2!$A:$A,Dashboard_2!$C$3,BodyMapData_2!$B:$B,$M7)=0,"", MAXIFS(BodyMapData_2!$E:$E,BodyMapData_2!$A:$A,Dashboard_2!$C$3,BodyMapData_2!$B:$B,$M7))
F8: L_Elbow | G8: 34 | H8: 65 | I8: =IFERROR(AVERAGEIFS(BodyMapData_2!$E:$E,BodyMapData_2!$C:$C,$F8,BodyMapData_2!$B:$B,Dashboard_2!$C$4,BodyMapData_2!$A:$A,Dashboard_2!$C$3),"") | J8: =IF($I8="","",G8) | K8: =IF($I8="","",H8) | N8: =IF(SUMIFS(BodyMapData_2!$E:$E,BodyMapData_2!$A:$A,Dashboard_2!$C$3,BodyMapData_2!$B:$B,$M8)=0,"", SUMIFS(BodyMapData_2!$E:$E,BodyMapData_2!$A:$A,Dashboard_2!$C$3,BodyMapData_2!$B:$B,$M8)) | O8: =IF(MAXIFS(BodyMapData_2!$E:$E,BodyMapData_2!$A:$A,Dashboard_2!$C$3,BodyMapData_2!$B:$B,$M8)=0,"", MAXIFS(BodyMapData_2!$E:$E,BodyMapData_2!$A:$A,Dashboard_2!$C$3,BodyMapData_2!$B:$B,$M8))
F9: L_ArmLower | G9: 36 | H9: 58 | I9: =IFERROR(AVERAGEIFS(BodyMapData_2!$E:$E,BodyMapData_2!$C:$C,$F9,BodyMapData_2!$B:$B,Dashboard_2!$C$4,BodyMapData_2!$A:$A,Dashboard_2!$C$3),"") | J9: =IF($I9="","",G9) | K9: =IF($I9="","",H9) | N9: =IF(SUMIFS(BodyMapData_2!$E:$E,BodyMapData_2!$A:$A,Dashboard_2!$C$3,BodyMapData_2!$B:$B,$M9)=0,"", SUMIFS(BodyMapData_2!$E:$E,BodyMapData_2!$A:$A,Dashboard_2!$C$3,BodyMapData_2!$B:$B,$M9)) | O9: =IF(MAXIFS(BodyMapData_2!$E:$E,BodyMapData_2!$A:$A,Dashboard_2!$C$3,BodyMapData_2!$B:$B,$M9)=0,"", MAXIFS(BodyMapData_2!$E:$E,BodyMapData_2!$A:$A,Dashboard_2!$C$3,BodyMapData_2!$B:$B,$M9))
F10: L_Wrist | G10: 88 | H10: 53 | I10: =IFERROR(AVERAGEIFS(BodyMapData_2!$E:$E,BodyMapData_2!$C:$C,$F10,BodyMapData_2!$B:$B,Dashboard_2!$C$4,BodyMapData_2!$A:$A,Dashboard_2!$C$3),"") | J10: =IF($I10="","",G10) | K10: =IF($I10="","",H10) | N10: =IF(SUMIFS(BodyMapData_2!$E:$E,BodyMapData_2!$A:$A,Dashboard_2!$C$3,BodyMapData_2!$B:$B,$M10)=0,"", SUMIFS(BodyMapData_2!$E:$E,BodyMapData_2!$A:$A,Dashboard_2!$C$3,BodyMapData_2!$B:$B,$M10)) | O10: =IF(MAXIFS(BodyMapData_2!$E:$E,BodyMapData_2!$A:$A,Dashboard_2!$C$3,BodyMapData_2!$B:$B,$M10)=0,"", MAXIFS(BodyMapData_2!$E:$E,BodyMapData_2!$A:$A,Dashboard_2!$C$3,BodyMapData_2!$B:$B,$M10))
F11: L_Hand | G11: 39 | H11: 49 | I11: =IFERROR(AVERAGEIFS(BodyMapData_2!$E:$E,BodyMapData_2!$C:$C,$F11,BodyMapData_2!$B:$B,Dashboard_2!$C$4,BodyMapData_2!$A:$A,Dashboard_2!$C$3),"") | J11: =IF($I11="","",G11) | K11: =IF($I11="","",H11) | N11: =IF(SUMIFS(BodyMapData_2!$E:$E,BodyMapData_2!$A:$A,Dashboard_2!$C$3,BodyMapData_2!$B:$B,$M11)=0,"", SUMIFS(BodyMapData_2!$E:$E,BodyMapData_2!$A:$A,Dashboard_2!$C$3,BodyMapData_2!$B:$B,$M11)) | O11: =IF(MAXIFS(BodyMapData_2!$E:$E,BodyMapData_2!$A:$A,Dashboard_2!$C$3,BodyMapData_2!$B:$B,$M11)=0,"", MAXIFS(BodyMapData_2!$E:$E,BodyMapData_2!$A:$A,Dashboard_2!$C$3,BodyMapData_2!$B:$B,$M11))
F12: R_Shoulder | G12: 11 | H12: 80 | I12: =IFERROR(AVERAGEIFS(BodyMapData_2!$E:$E,BodyMapData_2!$C:$C,$F12,BodyMapData_2!$B:$B,Dashboard_2!$C$4,BodyMapData_2!$A:$A,Dashboard_2!$C$3),"") | J12: =IF($I12="","",G12) | K12: =IF($I12="","",H12) | N12: =IF(SUMIFS(BodyMapData_2!$E:$E,BodyMapData_2!$A:$A,Dashboard_2!$C$3,BodyMapData_2!$B:$B,$M12)=0,"", SUMIFS(BodyMapData_2!$E:$E,BodyMapData_2!$A:$A,Dashboard_2!$C$3,BodyMapData_2!$B:$B,$M12)) | O12: =IF(MAXIFS(BodyMapData_2!$E:$E,BodyMapData_2!$A:$A,Dashboard_2!$C$3,BodyMapData_2!$B:$B,$M12)=0,"", MAXIFS(BodyMapData_2!$E:$E,BodyMapData_2!$A:$A,Dashboard_2!$C$3,BodyMapData_2!$B:$B,$M12))
F13: R_ArmUpper | G13: 10 | H13: 72 | I13: =IFERROR(AVERAGEIFS(BodyMapData_2!$E:$E,BodyMapData_2!$C:$C,$F13,BodyMapData_2!$B:$B,Dashboard_2!$C$4,BodyMapData_2!$A:$A,Dashboard_2!$C$3),"") | J13: =IF($I13="","",G13) | K13: =IF($I13="","",H13) | N13: =IF(SUMIFS(BodyMapData_2!$E:$E,BodyMapData_2!$A:$A,Dashboard_2!$C$3,BodyMapData_2!$B:$B,$M13)=0,"", SUMIFS(BodyMapData_2!$E:$E,BodyMapData_2!$A:$A,Dashboard_2!$C$3,BodyMapData_2!$B:$B,$M13)) | O13: =IF(MAXIFS(BodyMapData_2!$E:$E,BodyMapData_2!$A:$A,Dashboard_2!$C$3,BodyMapData_2!$B:$B,$M13)=0,"", MAXIFS(BodyMapData_2!$E:$E,BodyMapData_2!$A:$A,Dashboard_2!$C$3,BodyMapData_2!$B:$B,$M13))
F14: R_Elbow | G14: 9 | H14: 65 | I14: =IFERROR(AVERAGEIFS(BodyMapData_2!$E:$E,BodyMapData_2!$C:$C,$F14,BodyMapData_2!$B:$B,Dashboard_2!$C$4,BodyMapData_2!$A:$A,Dashboard_2!$C$3),"") | J14: =IF($I14="","",G14) | K14: =IF($I14="","",H14) | N14: =IF(SUMIFS(BodyMapData_2!$E:$E,BodyMapData_2!$A:$A,Dashboard_2!$C$3,BodyMapData_2!$B:$B,$M14)=0,"", SUMIFS(BodyMapData_2!$E:$E,BodyMapData_2!$A:$A,Dashboard_2!$C$3,BodyMapData_2!$B:$B,$M14)) | O14: =IF(MAXIFS(BodyMapData_2!$E:$E,BodyMapData_2!$A:$A,Dashboard_2!$C$3,BodyMapData_2!$B:$B,$M14)=0,"", MAXIFS(BodyMapData_2!$E:$E,BodyMapData_2!$A:$A,Dashboard_2!$C$3,BodyMapData_2!$B:$B,$M14))
F15: R_ArmLower | G15: 7 | H15: 58 | I15: =IFERROR(AVERAGEIFS(BodyMapData_2!$E:$E,BodyMapData_2!$C:$C,$F15,BodyMapData_2!$B:$B,Dashboard_2!$C$4,BodyMapData_2!$A:$A,Dashboard_2!$C$3),"") | J15: =IF($I15="","",G15) | K15: =IF($I15="","",H15) | N15: =IF(SUMIFS(BodyMapData_2!$E:$E,BodyMapData_2!$A:$A,Dashboard_2!$C$3,BodyMapData_2!$B:$B,$M15)=0,"", SUMIFS(BodyMapData_2!$E:$E,BodyMapData_2!$A:$A,Dashboard_2!$C$3,BodyMapData_2!$B:$B,$M15)) | O15: =IF(MAXIFS(BodyMapData_2!$E:$E,BodyMapData_2!$A:$A,Dashboard_2!$C$3,BodyMapData_2!$B:$B,$M15)=0,"", MAXIFS(BodyMapData_2!$E:$E,BodyMapData_2!$A:$A,Dashboard_2!$C$3,BodyMapData_2!$B:$B,$M15))
F16: R_Wrist | G16: 56 | H16: 53 | I16: =IFERROR(AVERAGEIFS(BodyMapData_2!$E:$E,BodyMapData_2!$C:$C,$F16,BodyMapData_2!$B:$B,Dashboard_2!$C$4,BodyMapData_2!$A:$A,Dashboard_2!$C$3),"") | J16: =IF($I16="","",G16) | K16: =IF($I16="","",H16) | N16: =IF(SUMIFS(BodyMapData_2!$E:$E,BodyMapData_2!$A:$A,Dashboard_2!$C$3,BodyMapData_2!$B:$B,$M16)=0,"", SUMIFS(BodyMapData_2!$E:$E,BodyMapData_2!$A:$A,Dashboard_2!$C$3,BodyMapData_2!$B:$B,$M16)) | O16: =IF(MAXIFS(BodyMapData_2!$E:$E,BodyMapData_2!$A:$A,Dashboard_2!$C$3,BodyMapData_2!$B:$B,$M16)=0,"", MAXIFS(BodyMapData_2!$E:$E,BodyMapData_2!$A:$A,Dashboard_2!$C$3,BodyMapData_2!$B:$B,$M16))
F17: R_Hand | G17: 4 | H17: 49 | I17: =IFERROR(AVERAGEIFS(BodyMapData_2!$E:$E,BodyMapData_2!$C:$C,$F17,BodyMapData_2!$B:$B,Dashboard_2!$C$4,BodyMapData_2!$A:$A,Dashboard_2!$C$3),"") | J17: =IF($I17="","",G17) | K17: =IF($I17="","",H17) | N17: =IF(SUMIFS(BodyMapData_2!$E:$E,BodyMapData_2!$A:$A,Dashboard_2!$C$3,BodyMapData_2!$B:$B,$M17)=0,"", SUMIFS(BodyMapData_2!$E:$E,BodyMapData_2!$A:$A,Dashboard_2!$C$3,BodyMapData_2!$B:$B,$M17)) | O17: =IF(MAXIFS(BodyMapData_2!$E:$E,BodyMapData_2!$A:$A,Dashboard_2!$C$3,BodyMapData_2!$B:$B,$M17)=0,"", MAXIFS(BodyMapData_2!$E:$E,BodyMapData_2!$A:$A,Dashboard_2!$C$3,BodyMapData_2!$B:$B,$M17))
F18: L_Chest | G18: 25 | H18: 75 | I18: =IFERROR(AVERAGEIFS(BodyMapData_2!$E:$E,BodyMapData_2!$C:$C,$F18,BodyMapData_2!$B:$B,Dashboard_2!$C$4,BodyMapData_2!$A:$A,Dashboard_2!$C$3),"") | J18: =IF($I18="","",G18) | K18: =IF($I18="","",H18) | N18: =IF(SUMIFS(BodyMapData_2!$E:$E,BodyMapData_2!$A:$A,Dashboard_2!$C$3,BodyMapData_2!$B:$B,$M18)=0,"", SUMIFS(BodyMapData_2!$E:$E,BodyMapData_2!$A:$A,Dashboard_2!$C$3,BodyMapData_2!$B:$B,$M18)) | O18: =IF(MAXIFS(BodyMapData_2!$E:$E,BodyMapData_2!$A:$A,Dashboard_2!$C$3,BodyMapData_2!$B:$B,$M18)=0,"", MAXIFS(BodyMapData_2!$E:$E,BodyMapData_2!$A:$A,Dashboard_2!$C$3,BodyMapData_2!$B:$B,$M18))
... F43: R_Calf | G43: 77 | H43: 18 | I43: =IFERROR(AVERAGEIFS(BodyMapData_2!$E:$E,BodyMapData_2!$C:$C,$F43,BodyMapData_2!$B:$B,Dashboard_2!$C$4,BodyMapData_2!$A:$A,Dashboard_2!$C$3),"") | J43: =IF($I43="","",G43) | K43: =IF($I43="","",H43) | N43: =IF(SUMIFS(BodyMapData_2!$E:$E,BodyMapData_2!$A:$A,Dashboard_2!$C$3,BodyMapData_2!$B:$B,$M43)=0,"", SUMIFS(BodyMapData_2!$E:$E,BodyMapData_2!$A:$A,Dashboard_2!$C$3,BodyMapData_2!$B:$B,$M43)) | O43: =IF(MAXIFS(BodyMapData_2!$E:$E,BodyMapData_2!$A:$A,Dashboard_2!$C$3,BodyMapData_2!$B:$B,$M43)=0,"", MAXIFS(BodyMapData_2!$E:$E,BodyMapData_2!$A:$A,Dashboard_2!$C$3,BodyMapData_2!$B:$B,$M43))
N44: =IF(SUMIFS(BodyMapData_2!$E:$E,BodyMapData_2!$A:$A,Dashboard_2!$C$3,BodyMapData_2!$B:$B,$M44)=0,"", SUMIFS(BodyMapData_2!$E:$E,BodyMapData_2!$A:$A,Dashboard_2!$C$3,BodyMapData_2!$B:$B,$M44)) | O44: =IF(MAXIFS(BodyMapData_2!$E:$E,BodyMapData_2!$A:$A,Dashboard_2!$C$3,BodyMapData_2!$B:$B,$M44)=0,"", MAXIFS(BodyMapData_2!$E:$E,BodyMapData_2!$A:$A,Dashboard_2!$C$3,BodyMapData_2!$B:$B,$M44))
N45: =IF(SUMIFS(BodyMapData_2!$E:$E,BodyMapData_2!$A:$A,Dashboard_2!$C$3,BodyMapData_2!$B:$B,$M45)=0,"", SUMIFS(BodyMapData_2!$E:$E,BodyMapData_2!$A:$A,Dashboard_2!$C$3,BodyMapData_2!$B:$B,$M45)) | O45: =IF(MAXIFS(BodyMapData_2!$E:$E,BodyMapData_2!$A:$A,Dashboard_2!$C$3,BodyMapData_2!$B:$B,$M45)=0,"", MAXIFS(BodyMapData_2!$E:$E,BodyMapData_2!$A:$A,Dashboard_2!$C$3,BodyMapData_2!$B:$B,$M45))
N46: =IF(SUMIFS(BodyMapData_2!$E:$E,BodyMapData_2!$A:$A,Dashboard_2!$C$3,BodyMapData_2!$B:$B,$M46)=0,"", SUMIFS(BodyMapData_2!$E:$E,BodyMapData_2!$A:$A,Dashboard_2!$C$3,BodyMapData_2!$B:$B,$M46)) | O46: =IF(MAXIFS(BodyMapData_2!$E:$E,BodyMapData_2!$A:$A,Dashboard_2!$C$3,BodyMapData_2!$B:$B,$M46)=0,"", MAXIFS(BodyMapData_2!$E:$E,BodyMapData_2!$A:$A,Dashboard_2!$C$3,BodyMapData_2!$B:$B,$M46))
N47: =IF(SUMIFS(BodyMapData_2!$E:$E,BodyMapData_2!$A:$A,Dashboard_2!$C$3,BodyMapData_2!$B:$B,$M47)=0,"", SUMIFS(BodyMapData_2!$E:$E,BodyMapData_2!$A:$A,Dashboard_2!$C$3,BodyMapData_2!$B:$B,$M47)) | O47: =IF(MAXIFS(BodyMapData_2!$E:$E,BodyMapData_2!$A:$A,Dashboard_2!$C$3,BodyMapData_2!$B:$B,$M47)=0,"", MAXIFS(BodyMapData_2!$E:$E,BodyMapData_2!$A:$A,Dashboard_2!$C$3,BodyMapData_2!$B:$B,$M47))
N48: =IF(SUMIFS(BodyMapData_2!$E:$E,BodyMapData_2!$A:$A,Dashboard_2!$C$3,BodyMapData_2!$B:$B,$M48)=0,"", SUMIFS(BodyMapData_2!$E:$E,BodyMapData_2!$A:$A,Dashboard_2!$C$3,BodyMapData_2!$B:$B,$M48)) | O48: =IF(MAXIFS(BodyMapData_2!$E:$E,BodyMapData_2!$A:$A,Dashboard_2!$C$3,BodyMapData_2!$B:$B,$M48)=0,"", MAXIFS(BodyMapData_2!$E:$E,BodyMapData_2!$A:$A,Dashboard_2!$C$3,BodyMapData_2!$B:$B,$M48))
N49: =IF(SUMIFS(BodyMapData_2!$E:$E,BodyMapData_2!$A:$A,Dashboard_2!$C$3,BodyMapData_2!$B:$B,$M49)=0,"", SUMIFS(BodyMapData_2!$E:$E,BodyMapData_2!$A:$A,Dashboard_2!$C$3,BodyMapData_2!$B:$B,$M49)) | O49: =IF(MAXIFS(BodyMapData_2!$E:$E,BodyMapData_2!$A:$A,Dashboard_2!$C$3,BodyMapData_2!$B:$B,$M49)=0,"", MAXIFS(BodyMapData_2!$E:$E,BodyMapData_2!$A:$A,Dashboard_2!$C$3,BodyMapData_2!$B:$B,$M49))
N50: =IF(SUMIFS(BodyMapData_2!$E:$E,BodyMapData_2!$A:$A,Dashboard_2!$C$3,BodyMapData_2!$B:$B,$M50)=0,"", SUMIFS(BodyMapData_2!$E:$E,BodyMapData_2!$A:$A,Dashboard_2!$C$3,BodyMapData_2!$B:$B,$M50)) | O50: =IF(MAXIFS(BodyMapData_2!$E:$E,BodyMapData_2!$A:$A,Dashboard_2!$C$3,BodyMapData_2!$B:$B,$M50)=0,"", MAXIFS(BodyMapData_2!$E:$E,BodyMapData_2!$A:$A,Dashboard_2!$C$3,BodyMapData_2!$B:$B,$M50))
N51: =IF(SUMIFS(BodyMapData_2!$E:$E,BodyMapData_2!$A:$A,Dashboard_2!$C$3,BodyMapData_2!$B:$B,$M51)=0,"", SUMIFS(BodyMapData_2!$E:$E,BodyMapData_2!$A:$A,Dashboard_2!$C$3,BodyMapData_2!$B:$B,$M51)) | O51: =IF(MAXIFS(BodyMapData_2!$E:$E,BodyMapData_2!$A:$A,Dashboard_2!$C$3,BodyMapData_2!$B:$B,$M51)=0,"", MAXIFS(BodyMapData_2!$E:$E,BodyMapData_2!$A:$A,Dashboard_2!$C$3,BodyMapData_2!$B:$B,$M51))
N52: =IF(SUMIFS(BodyMapData_2!$E:$E,BodyMapData_2!$A:$A,Dashboard_2!$C$3,BodyMapData_2!$B:$B,$M52)=0,"", SUMIFS(BodyMapData_2!$E:$E,BodyMapData_2!$A:$A,Dashboard_2!$C$3,BodyMapData_2!$B:$B,$M52)) | O52: =IF(MAXIFS(BodyMapData_2!$E:$E,BodyMapData_2!$A:$A,Dashboard_2!$C$3,BodyMapData_2!$B:$B,$M52)=0,"", MAXIFS(BodyMapData_2!$E:$E,BodyMapData_2!$A:$A,Dashboard_2!$C$3,BodyMapData_2!$B:$B,$M52))
N53: =IF(SUMIFS(BodyMapData_2!$E:$E,BodyMapData_2!$A:$A,Dashboard_2!$C$3,BodyMapData_2!$B:$B,$M53)=0,"", SUMIFS(BodyMapData_2!$E:$E,BodyMapData_2!$A:$A,Dashboard_2!$C$3,BodyMapData_2!$B:$B,$M53)) | O53: =IF(MAXIFS(BodyMapData_2!$E:$E,BodyMapData_2!$A:$A,Dashboard_2!$C$3,BodyMapData_2!$B:$B,$M53)=0,"", MAXIFS(BodyMapData_2!$E:$E,BodyMapData_2!$A:$A,Dashboard_2!$C$3,BodyMapData_2!$B:$B,$M53))
N54: =IF(SUMIFS(BodyMapData_2!$E:$E,BodyMapData_2!$A:$A,Dashboard_2!$C$3,BodyMapData_2!$B:$B,$M54)=0,"", SUMIFS(BodyMapData_2!$E:$E,BodyMapData_2!$A:$A,Dashboard_2!$C$3,BodyMapData_2!$B:$B,$M54)) | O54: =IF(MAXIFS(BodyMapData_2!$E:$E,BodyMapData_2!$A:$A,Dashboard_2!$C$3,BodyMapData_2!$B:$B,$M54)=0,"", MAXIFS(BodyMapData_2!$E:$E,BodyMapData_2!$A:$A,Dashboard_2!$C$3,BodyMapData_2!$B:$B,$M54))
N55: =IF(SUMIFS(BodyMapData_2!$E:$E,BodyMapData_2!$A:$A,Dashboard_2!$C$3,BodyMapData_2!$B:$B,$M55)=0,"", SUMIFS(BodyMapData_2!$E:$E,BodyMapData_2!$A:$A,Dashboard_2!$C$3,BodyMapData_2!$B:$B,$M55)) | O55: =IF(MAXIFS(BodyMapData_2!$E:$E,BodyMapData_2!$A:$A,Dashboard_2!$C$3,BodyMapData_2!$B:$B,$M55)=0,"", MAXIFS(BodyMapData_2!$E:$E,BodyMapData_2!$A:$A,Dashboard_2!$C$3,BodyMapData_2!$B:$B,$M55))
... N362: =IF(SUMIFS(BodyMapData_2!$E:$E,BodyMapData_2!$A:$A,Dashboard_2!$C$3,BodyMapData_2!$B:$B,$M362)=0,"", SUMIFS(BodyMapData_2!$E:$E,BodyMapData_2!$A:$A,Dashboard_2!$C$3,BodyMapData_2!$B:$B,$M362)) | O362: =IF(MAXIFS(BodyMapData_2!$E:$E,BodyMapData_2!$A:$A,Dashboard_2!$C$3,BodyMapData_2!$B:$B,$M362)=0,"", MAXIFS(BodyMapData_2!$E:$E,BodyMapData_2!$A:$A,Dashboard_2!$C$3,BodyMapData_2!$B:$B,$M362))
O363: =IF(MAXIFS(BodyMapData_2!$E:$E,BodyMapData_2!$A:$A,Dashboard_2!$C$3,BodyMapData_2!$B:$B,$M363)=0,"", MAXIFS(BodyMapData_2!$E:$E,BodyMapData_2!$A:$A,Dashboard_2!$C$3,BodyMapData_2!$B:$B,$M363))
O364: =IF(MAXIFS(BodyMapData_2!$E:$E,BodyMapData_2!$A:$A,Dashboard_2!$C$3,BodyMapData_2!$B:$B,$M364)=0,"", MAXIFS(BodyMapData_2!$E:$E,BodyMapData_2!$A:$A,Dashboard_2!$C$3,BodyMapData_2!$B:$B,$M364))
O365: =IF(MAXIFS(BodyMapData_2!$E:$E,BodyMapData_2!$A:$A,Dashboard_2!$C$3,BodyMapData_2!$B:$B,$M365)=0,"", MAXIFS(BodyMapData_2!$E:$E,BodyMapData_2!$A:$A,Dashboard_2!$C$3,BodyMapData_2!$B:$B,$M365))
O366: =IF(MAXIFS(BodyMapData_2!$E:$E,BodyMapData_2!$A:$A,Dashboard_2!$C$3,BodyMapData_2!$B:$B,$M366)=0,"", MAXIFS(BodyMapData_2!$E:$E,BodyMapData_2!$A:$A,Dashboard_2!$C$3,BodyMapData_2!$B:$B,$M366))
O367: =IF(MAXIFS(BodyMapData_2!$E:$E,BodyMapData_2!$A:$A,Dashboard_2!$C$3,BodyMapData_2!$B:$B,$M367)=0,"", MAXIFS(BodyMapData_2!$E:$E,BodyMapData_2!$A:$A,Dashboard_2!$C$3,BodyMapData_2!$B:$B,$M367))
O368: =IF(MAXIFS(BodyMapData_2!$E:$E,BodyMapData_2!$A:$A,Dashboard_2!$C$3,BodyMapData_2!$B:$B,$M368)=0,"", MAXIFS(BodyMapData_2!$E:$E,BodyMapData_2!$A:$A,Dashboard_2!$C$3,BodyMapData_2!$B:$B,$M368))
O369: =IF(MAXIFS(BodyMapData_2!$E:$E,BodyMapData_2!$A:$A,Dashboard_2!$C$3,BodyMapData_2!$B:$B,$M369)=0,"", MAXIFS(BodyMapData_2!$E:$E,BodyMapData_2!$A:$A,Dashboard_2!$C$3,BodyMapData_2!$B:$B,$M369))
O370: =IF(MAXIFS(BodyMapData_2!$E:$E,BodyMapData_2!$A:$A,Dashboard_2!$C$3,BodyMapData_2!$B:$B,$M370)=0,"", MAXIFS(BodyMapData_2!$E:$E,BodyMapData_2!$A:$A,Dashboard_2!$C$3,BodyMapData_2!$B:$B,$M370))
...

Sheet Dashboard_1
A3: Select Athlete | B3: Harry Bird
A4: Select Date | B4: 43922
A6: =IFERROR(__xludf.DUMMYFUNCTION("FILTER(XYs_1!F:F,XYs_1!I:I>0)"),"Part") -> Part | B6: =IFERROR(__xludf.DUMMYFUNCTION("FILTER(XYs_1!I:I,XYs_1!I:I>0)"),"Athlete Value") -> Athlete Value
A7: =IFERROR(__xludf.DUMMYFUNCTION("""COMPUTED_VALUE"""),"Head") -> Head | B7: =IFERROR(__xludf.DUMMYFUNCTION("""COMPUTED_VALUE"""),1.0) -> 1
A8: =IFERROR(__xludf.DUMMYFUNCTION("""COMPUTED_VALUE"""),"R_ArmLower") -> R_ArmLower | B8: =IFERROR(__xludf.DUMMYFUNCTION("""COMPUTED_VALUE"""),4.0) -> 4
A9: =IFERROR(__xludf.DUMMYFUNCTION("""COMPUTED_VALUE"""),"R_Calf") -> R_Calf | B9: =IFERROR(__xludf.DUMMYFUNCTION("""COMPUTED_VALUE"""),3.0) -> 3

Sheet Dashboard_2
A1: INTERACTIVE BODY MAP DASHBOARD
A3: SELECT ATHLETE | C3: Harry Bird
A4: SELECT DATE | C4: 43922
A6: =IFERROR(__xludf.DUMMYFUNCTION("FILTER(XYs_2!F:F,XYs_2!I:I<>"""")"),"Part") -> Part | B6: =IFERROR(__xludf.DUMMYFUNCTION("FILTER(XYs_2!I:I,XYs_2!I:I<>"""")"),"Athlete Value") -> Athlete Value | C6: Average
A7: =IFERROR(__xludf.DUMMYFUNCTION("""COMPUTED_VALUE"""),"Head") -> Head | B7: =IFERROR(__xludf.DUMMYFUNCTION("""COMPUTED_VALUE"""),1.0) -> 1 | C7: =IFERROR(AVERAGEIFS(BodyMapData_2!$E:$E,BodyMapData_2!$A:$A,$C$3,BodyMapData_2!$C:$C,$A7),"") -> 2
A8: =IFERROR(__xludf.DUMMYFUNCTION("""COMPUTED_VALUE"""),"R_Knee") -> R_Knee | B8: =IFERROR(__xludf.DUMMYFUNCTION("""COMPUTED_VALUE"""),5.0) -> 5 | C8: =IFERROR(AVERAGEIFS(BodyMapData_2!$E:$E,BodyMapData_2!$A:$A,$C$3,BodyMapData_2!$C:$C,$A8),"") -> 6
A9: =IFERROR(__xludf.DUMMYFUNCTION("""COMPUTED_VALUE"""),"R_Foot") -> R_Foot | B9: =IFERROR(__xludf.DUMMYFUNCTION("""COMPUTED_VALUE"""),1.0) -> 1 | C9: =IFERROR(AVERAGEIFS(BodyMapData_2!$E:$E,BodyMapData_2!$A:$A,$C$3,BodyMapData_2!$C:$C,$A9),"") -> 1.3333333
C10: =IFERROR(AVERAGEIFS(BodyMapData_2!$E:$E,BodyMapData_2!$A:$A,$C$3,BodyMapData_2!$C:$C,$A10),"")
C11: =IFERROR(AVERAGEIFS(BodyMapData_2!$E:$E,BodyMapData_2!$A:$A,$C$3,BodyMapData_2!$C:$C,$A11),"")
C12: =IFERROR(AVERAGEIFS(BodyMapData_2!$E:$E,BodyMapData_2!$A:$A,$C$3,BodyMapData_2!$C:$C,$A12),"")
C13: =IFERROR(AVERAGEIFS(BodyMapData_2!$E:$E,BodyMapData_2!$A:$A,$C$3,BodyMapData_2!$C:$C,$A13),"")
C14: =IFERROR(AVERAGEIFS(BodyMapData_2!$E:$E,BodyMapData_2!$A:$A,$C$3,BodyMapData_2!$C:$C,$A14),"")
C15: =IFERROR(AVERAGEIFS(BodyMapData_2!$E:$E,BodyMapData_2!$A:$A,$C$3,BodyMapData_2!$C:$C,$A15),"")
C16: =IFERROR(AVERAGEIFS(BodyMapData_2!$E:$E,BodyMapData_2!$A:$A,$C$3,BodyMapData_2!$C:$C,$A16),"")
C17: =IFERROR(AVERAGEIFS(BodyMapData_2!$E:$E,BodyMapData_2!$A:$A,$C$3,BodyMapData_2!$C:$C,$A17),"")
C18: =IFERROR(AVERAGEIFS(BodyMapData_2!$E:$E,BodyMapData_2!$A:$A,$C$3,BodyMapData_2!$C:$C,$A18),"")
C19: =IFERROR(AVERAGEIFS(BodyMapData_2!$E:$E,BodyMapData_2!$A:$A,$C$3,BodyMapData_2!$C:$C,$A19),"")
C20: =IFERROR(AVERAGEIFS(BodyMapData_2!$E:$E,BodyMapData_2!$A:$A,$C$3,BodyMapData_2!$C:$C,$A20),"")
