Workbook

Sheet INTRO
A1: Guide to Sports Analytics
A5: Introduction | J5: About
A7: - Hello there! Welcome to a compherensive guide to sports analytics that I've put together over the pasts few years. - Here, you'll find an extensive list of coding tutorials, sports analysts to follow, books/blogs, web apps, research papers, & more! - Most importantly, none of this would be possible without the public work of all the great sports analysts out there! Nearly 99% of everything listed has been produced by others, so in no way do I claim it as my own. The SA community is incredible! - The goal of this is to showcase the best work, coding tutorials, and overall learning materials in order to lower the barrier to entry for those that are interested in the sports analytics field! - Feel free to follow myself (@DSamangy) and those listed throughout on Twitter. Always open to answering any questions! - As of now, the guide covers the following four analytical softwares: - R: an open-source programming language that is widely used as a statistical software, graphics, data analysis tool. - Python: a computer programming language used to build websites, software, automate tasks, & conduct data analysis. - Tableau: a leading data visualization tool used for data analysis and business intelligence. - SQL: a computer language for storing, manipulating and retrieving data stored in a relational database.
J8: Dominic Samangy - I’m currently the Basketball Analytics Coordinator for the New Orleans Pelicans with past experience with the Arkansas ('22-'23) and Syracuse ('18-'22) Men's Basketball Programs. - Prior to New Orleans, I worked with several NBA trainers, players, and agencies. I’ve also partaken in research projects & competitions. In April 2022, I led a group of undergraduate classmates as we won the Milwaukee Bucks’ inaugural basketball analytics hackathon. I’ve also presented co-authored research at the MIT Sloan Sports Analytics Conference, the Carnegie Mellon Sports Analytics Conference, the Midwest Analytics Conference, and the 8th Western Football and Finance Conference in London. My Timeline: New Orleans Pelicans (2023-Present) - Basketball Analytics Coordinator NBA Analytics Consultant (2021-2023) - Player Development, Scouting, and Draft Arkansas MBB (2022-2023) - Grad Assistant Coach & Analytics Coordinator Syracuse MBB (2018-22) - Student Manager
L20: Twitter: | M20: @DSamangy
L21: LinkedIn: | M21: DomSamangy
L22: YouTube: | M22: @domsamangy
L23: GitHub: | M23: DomSamangy

Sheet How to Start
A1: How to Get Started in Sports Analytics
A5: General Steps
A7: 1. Read/Listen to Media & Personal Experiences: - There's no better way to explore a new industry than to hear about personal experiences and success stories from those that have been through the journey of working in sports. - There are several ways to find these invaluable stories: - Podcasts // Articles // Blog Posts // Books - *See the blogs/books or articles tabs below. - Finding and listenting to these personal stories will help you better understand what it takes to be successful and may also give you a better idea of your own specific areas of interest in the sports analytics realm. - It can be great to explore other sports outside of your end goal. I started out in soccer analytics and is where most of my initial work was focused due to more readily available data sources and coding tutorials. - Analytical/programming skills translate easily from sport-to-sport. - Data analysis, modeling, software development, etc. - Just a few areas of sports analytics to explore: - Teams: Coaching Strategy // Player & Team Scouting // Video - Front Office: Modelling & Projections // Scouting // Cap Strategy - Performance: Strength & Conditioning // Mental Performance - Programming: Database Engineer // Full-Stack Developer - Business: Ticket Sales // Marketing // Branding | F7: 2. Build a Skillset & Portfolio through Personal Projects: - Once you have identified potential areas of interest, it's crucial to begin your journey of building your own skillset and portfolio through personal projects and experiences. - Types of valuable "analytics" skills/jobs: - Data Analysis: - Apply statistical technqiues to analzye and describe datasets. - Data Scientist: - Apply modelling technqiues to explain and predict data. - Database Managament: - Create, protect, read, update and delete data. - Software Development: - Process of creating, designing and supporting applications. - Could specialize in front-end (website) or back-end (data) of app. - Types of projects to create: - Coaching: Scouting Report // Postgame Report // In-Game Strategy - Front Office: Draft Model // Career Projections // Player Skills Model - Performance: Player Load Reports // Recovery Time Projections - Programming: Web App for Interal Use // Database Creation - Business: Fan Demographics Study // Ticket Sales Projections | K7: 3. Create Connections in the Industry - "Your net worth is your network". - "Managers want to know that you can do the job, before you have the job". - "Who knows what you can do" >>> "Who knows who". - The sports world is much smaller and closely connected than you think. - Be honest and treat people well and it will return. - Your portfolio and resume help you get considered for potential jobs, while your connections help you get hired. - Unfortunately, a lot of jobs in sports are filled behind closed doors through "connections-based" interview pools. - Every job or freelance opportunity that I've held in my career has come to fruition through previous experiences and connections. - Ways to get connected to industry professionals. - Blind emails and LinkedIn messages to introduce yourself. - Informational phone or zoom calls to ask questions. - In-person events: NBA Summer League, conferences, job fairs, etc. - After creating relationships through these, ask your new connection if there is anyone they could help you meet. - Stay in contact by checking in (people are busy during the season!!). I have and still use my friends/connections for feedback on my own work as well. Best way to showcase what you can do. - Rinse and Repeat

Sheet R Tutorials
A1: R Tutorials
A3: Subject | B3: Type | C3: Description | D3: Link | E3: Sport (if applicable)
A4: Mac - R Studio Install | B4: Intro | C4: HOW TO DOWNLOAD AND INSTALL R STUDIO (Mac) | D4: https://www.youtube.com/watch?v=cCgiR1uwXzU | E4: General
A5: Windows - R Studio Install | B5: Intro | C5: HOW TO DOWNLOAD AND INSTALL R STUDIO (Windows) | D5: https://www.youtube.com/watch?v=UTFxSn-N2Ps | E5: General
A7: R YouTube tutorial | B7: Data viz | C7: Basketball shot chart video tutorial w/ code | D7: https://youtu.be/Af7g95-g4y8 | E7: Basketball
A8: R YouTube tutorial | B8: Data viz | C8: Basketball and soccer heatmapps video tutorial w/ code | D8: https://youtu.be/rBBVSmFJqyE | E8: Basketball | F8: Soccer (football)
A9: R YouTube tutorial | B9: Data viz & scraping | C9: Web scraping (rvest) & scatter plot video tutorial w/ code | D9: https://youtu.be/W9BOBFWAdxc | E9: Basketball | F9: Soccer (football)
A10: R YouTube tutorial | B10: Data viz | C10: NBA & soccer polar/pizza plot tutorial w/ code | D10: https://www.youtube.com/watch?v=56mA8j33LbQ&list=PL10a1_q15Hwr4H5dCXQD3htK5VGfwjrgq&index=4 | E10: Basketball | F10: Soccer (football)
A11: R YouTube tutorial | B11: Data viz | C11: How to manually create and plot event sports data w/ code | D11: https://www.youtube.com/watch?v=vrVwofFpsV0&list=PL10a1_q15Hwr4H5dCXQD3htK5VGfwjrgq&index=5 | E11: Basketball | F11: Soccer (football)
A12: R YouTube tutorial | B12: Data viz | C12: How to create a soccer shotmap in R | D12: https://www.youtube.com/watch?v=Cn4Vt5DVWYw&t=447s | E12: Soccer (football)
A13: R YouTube tutorial | B13: Data viz | C13: How to create bar charts in R | D13: https://www.youtube.com/watch?v=5i-2rFtbIIU&t=885s | E13: Basketball
A14: R YouTube tutorial | B14: Data viz | C14: Tidyverse (DPLyR) Beginners Tutorial in R | D14: https://www.youtube.com/watch?v=VB39imrMwoc&t=348s | E14: General
A16: CBBData API | B16: Tutorial | C16: CBBData, Your Gateway to In-Depth College Basketball Insights | D16: https://cbbdata.aweatherman.com/ | E16: Basketball
A17: cbbplotR | B17: Tutorial | C17: cbbplotR: Your Gateway to CBB Visualization in R | D17: https://cbbplotr.aweatherman.com/articles/getting_started.html | E17: Basketball
A18: Buckeys & Bytes | B18: Blog Tutorials | C18: UNREAL basketball-based blog with in-depth R tutorials | D18: https://aweatherman.substack.com/ | E18: Basketball
A19: NbainRstats | B19: Blog Tutorials | C19: "Reproducing NBA advanced stats in R" | D19: https://nbainrstats.netlify.app/ | E19: Basketball
A20: NBA R tutorials | B20: Comprehensive | C20: Tutorials on various basketball related topics | D20: https://github.com/anpatton/basic-nba-tutorials | E20: Basketball
A21: shot charts | B21: Data viz | C21: Tutorial on creating a variety of shot charts | D21: https://thedatagame.com.au/2015/09/27/how-to-create-nba-shot-charts-in-r/ | E21: Basketball
A22: NBA shot charts | B22: Data viz | C22: YouTube tutorial to create NBA shot charts w/ code | D22: https://www.youtube.com/watch?v=ZQ8fqSnvWcc | E22: Basketball
A23: scraping basketball-reference | B23: Scraping | C23: Walkthrough to scrape basketball reference tables | D23: https://statisticaloddsandends.wordpress.com/2018/12/11/scraping-nba-game-data-from-basketball-reference-com/ | E23: Basketball
A24: scraping basketball-reference | B24: Scraping | C24: Walkthrough to scrape basketball reference tables | D24: https://statisticaloddsandends.wordpress.com/2018/12/11/scraping-nba-game-data-from-basketball-reference-com/ | E24: Basketball
... A88: INTRO TO R (intRo) | B88: Intro | C88: Amazing intro tutorial that teaches R in a tidyverse style. | D88: https://github.com/billyfryer/intRo-Tutorials | E88: General

Sheet R Packages
A1: R Packages
A3: Website/Package | B3: Description | C3: Link | D3: Sport
A4: PySport open source | B4: One of the BEST resources! Has links to packages in all sports in many languages | C4: https://opensource.pysport.org/ | D4: All sports
A5: teamcolors | B5: Package to pull team colors palettes for pro sports teams | C5: https://github.com/beanumber/teamcolors | D5: All sports
A6: sportyR | B6: Allows for customized sports fields/courts & displaying player tracking data | C6: https://github.com/rossdrucker/sportyR/ | D6: All sports
A7: Sports dataverse | B7: Open-source sports data packages to foster more diversity and inclusion within sports analytics | C7: https://sportsdataverse.org/ | D7: All sports
A9: CBBData API | B9: R package: "Your Gateway to In-Depth College Basketball Insights" | C9: https://cbbdata.aweatherman.com/articles/release.html | D9: Basketball (NCAA)
A10: cbbplotR | B10: R package designed to bring the vibrant world of college basketball into your data visualizations | C10: https://github.com/andreweatherman/cbbplotR | D10: Basketball (NCAA)
A11: Basketball Reference | B11: NBA & NCAA data | C11: https://basketball-reference.com | D11: Basketball (NBA & NCAA)
A12: NBA.com stats | B12: NBA data | C12: https://www.nba.com/stats/ | D12: Basketball (NBA)
A13: nbastatR | B13: NBA package to pull data from numerous basketball data sites | C13: https://www.rdocumentation.org/packages/nbastatR/versions/0.1.110202031 | D13: Basketball (NBA)
A14: nbastatR | B14: Resource that explains each function in nbastatR | C14: http://asbcllc.com/nbastatR/reference/index.html | D14: Basketball (NBA)
A15: ballr | B15: Package to create awesome plots using NBA data | C15: https://github.com/toddwschneider/ballr | D15: Basketball (NBA)
... A52: hockeyR | B52: Contains various functions to scrape and clean play-by-play data from NHL.com | C52: https://github.com/danmorse314/hockeyR | D52: Hockey
A54: Introverse | B54: Package that aims to provide beginner-oriented help within R | C54: https://spielmanlab.github.io/introverse/
A55: JSON to CSV | B55: Seamless tool to convert JSON data to CSV file | C55: https://konklone.io/json/
A57: Tidymodels google sheet | B57: All-in-one google sheet with extensive notes and links (@EatsleepfitJeff) | C57: https://docs.google.com/spreadsheets/d/1PzbtanwieCCpaUt9G6XMhKXQ_0cBWfq_9xG9bH33Occ/edit#gid=652338894

Sheet R Accounts
A1: R Accounts to Follow
A3: Account @ | B3: Description | C3: Link | D3: Sport
A4: @DSamangy | B4: Data viz, shiny apps, player video breakdowns | C4: @DSamangy | D4: Basketball
A5: ="@andrewweatherman" -> @andrewweatherman | B5: Elite data viz follow w/ tutorials (Duke grad unfortunately) | C5: @andrewweatherman | D5: Basketball
A6: @CrumpledJumper | B6: Data viz, shiny apps | C6: @CrumpledJumper | D6: Basketball
A7: @owenlhjphillips | B7: Data viz, newsletter (https://thef5.substack.com/) | C7: @owenlhjphillips | D7: Basketball
A8: @NbaInRstats | B8: NBA blog posts w/ reporucible code | C8: @NbaInRstats | D8: Basketball
A9: @scottdaughtry5 | B9: Coaching & performance analytics. Former Pacers intern | C9: @scottdaughtry5 | D9: Basketball
A10: @CFL1GHT | B10: Coaching analytics engineer & analyst. Formerly: Milwaukee Bucks. | C10: @CFL1GHT | D10: Basketball
A11: @burakcankoc | B11: Data viz, shiny apps, | C11: @burakcankoc | D11: Basketball
A12: @SaurabhOnTap | B12: Visualizations and extensive shiny apps | C12: @SaurabhOnTap | D12: Basketball
A13: @anpatt7 | B13: Data viz, shiny app, tutorials | C13: @anpatt7 | D13: Basketball
A14: @recspecs730 | B14: Data viz, ncaahoopR package, tutorials | C14: @recspecs730 | D14: Basketball
A15: @tvbassine | B15: Data viz, https://threesandlayups.com/ blog | C15: @tvbassine | D15: Basketball
A16: @arjun_balaraman | B16: Data viz, shiny apps | C16: @arjun_balaraman | D16: Basketball
A17: @Peter_Zanca | B17: Data viz, shiny apps | C17: @Peter_Zanca | D17: Basketball
... A85: @tanya_shapiro | B85: Very cool R data viz. Walks through her progress w/ code. | C85: @tanya_shapiro | D85: R Blogger

Sheet Py Tutorials
A1: Python Tutorials
A3: Subject | B3: Type | C3: Description | D3: Link | E3: Sport (if applicable) | F3: Code | G3: Data
A4: Mac - Python Install | B4: Intro | C4: HOW TO DOWNLOAD & INSTALL ANACONDA PYTHON/JUPYTER (Mac) | D4: https://www.youtube.com/watch?v=PJWnGNWQ1Dc | E4: General
A5: Mac - Python Install | B5: Intro | C5: HOW TO DOWNLOAD & INSTALL ANACONDA PYTHON/JUPYTER (Mac) | D5: https://www.youtube.com/watch?v=YA8Nq8Tlma4 | E5: General
A6: Windows - R Python Install | B6: Intro | C6: HOW TO DOWNLOAD & INSTALL ANACONDA PYTHON/JUPYTER (Windows) | D6: https://www.youtube.com/watch?v=-sNX_ZMVpQM | E6: General
A8: YouTube Tutorial | B8: General Advice | C8: 3 tips to getting started in sports analytics | D8: https://www.youtube.com/watch?v=xyC7SbmNp-I | E8: All Sports
A9: Matplotlib official tutorial | B9: Data Viz | C9: In-depth Matplotlib guide. Beginner, intermediate, and advanced | D9: https://matplotlib.org/stable/tutorials/index.html | E9: General Data Viz
A10: Matplotlib tutorial | B10: Data Viz | C10: MASSIVE Matplotlib tutorial page w/ all plots | D10: https://www.geeksforgeeks.org/matplotlib-tutorial/?ref=lbp | E10: General Data Viz
A11: Blog series tutorial | B11: Pandas | C11: Noterbook series to understanding Pandas | D11: https://github.com/TomAugspurger/effective-pandas | E11: General Data Viz
A12: Plot tutorial collection | B12: Data viz | C12: Reproducible data viz tutorials (BIG) | D12: https://www.r-graph-gallery.com/index.html | E12: General Data Viz
A14: Mckay Johns | B14: Data Course | C14: "The Complete Football Analytics in Python Course" | D14: https://mckay-s-site.thinkific.com/courses/football-analytics-course | E14: Soccer (football)
A15: YouTube Tutorial | B15: Data viz | C15: How to create a soccer/football pitch in Python | D15: https://www.youtube.com/watch?v=55k1mCRyd2k | E15: Soccer (football)
A16: YouTube Tutorial | B16: Data viz | C16: How to create a soccer pass map in Python | D16: https://www.youtube.com/watch?v=Qx0F1QjOq5A | E16: Soccer (football)
A17: YouTube Tutorial | B17: Data viz | C17: How to create soccer pass heatmaps in Python | D17: https://www.youtube.com/watch?v=N46zGdX_xsY | E17: Soccer (football)
... A26: Python blog post | B26: Data viz | C26: Football Data Visualizations - Passing Networks | D26: https://www.dzialowski.eu/football-data-visualisations/ | E26: Soccer (football)
A27: YouTube Series | B27: Data Science | C27: LaurieOnTracking - code to working with metrica tracking data | D27: https://github.com/Friends-of-Tracking-Data-FoTD/LaurieOnTracking | E27: Soccer (football) | G27: https://github.com/metrica-sports/sample-data
A28: Friends of Tracking | B28: Data Science | C28: This series of videos covering MANY aspects of soccer analytics. | D28: https://www.youtube.com/playlist?list=PLedeYskZY0vBOdQ6Uc9eZjZ2-nz1JT3R7 | E28: Soccer (football)
A29: Matplotlib soccer tutorials | B29: Data viz | C29: Step by step tutorials to amazing visuals using soccer data. | D29: https://www.sonofacorner.com/tag/tutorials/ | E29: Soccer (football)
A31: Github blog | B31: Data Science | C31: Basic NBA tutorials in Python | D31: https://github.com/anpatton/basic-nba-tutorials | E31: Basketball (NBA)
A32: Github blog | B32: Data Science | C32: NBA Data processing tutorials | D32: https://github.com/rd11490/NBA_Tutorials | E32: Basketball (NBA)
A33: pandas, matplotlib | B33: Data viz | C33: NBA single shot chart tutorial in Python | D33: https://www.visualnoise.io/nba-shot-data-analytics-visualization-with-python-pandas-and-matplotlib-part-1-the-basics/ | E33: Basketball (NBA) | H33: part 1
A34: pandas, matplotlib | B34: Data viz | C34: NBA hexbin shot chart tutorial in Python | D34: https://www.visualnoise.io/nba-shot-data-analytics-visualization-with-python-pandas-and-matplotlib-part-2-grouping-data-by-area/ | E34: Basketball (NBA) | H34: part 2
A35: pandas, matplotlib | B35: Data viz | C35: NBA hexbin w/ color scales shot chart tutorial in Python | D35: https://www.visualnoise.io/nba-shot-data-analytics-visualization-with-python-pandas-and-matplotlib-part-3/ | E35: Basketball (NBA) | H35: part 3
A36: pandas, matplotlib | B36: Data viz | C36: Interactive NBA hexbin w/ color scales | D36: https://www.visualnoise.io/interactive-basketball-data-visualizations-with-plotly/ | E36: Basketball (NBA) | H36: part 4
A37: pandas, matplotlib | B37: Data viz | C37: NBA hex shot chart tutorial in Python | D37: https://towardsdatascience.com/make-a-simple-nba-shot-chart-with-python-e5d70db45d0d | E37: Basketball (NBA)
A38: Basketball-ref scraping | B38: Web scraping | C38: Web Scraping NBA Stats With Python | D38: https://www.youtube.com/watch?v=JGQGd-oa0l4 | E38: Basketball (NBA) | F38: https://github.com/dataquestio/project-walkthroughs/blob/master/mvp/web_scraping.ipynb | H38: part 1
A39: Basketball data cleaning | B39: Data cleaning | C39: Cleaning NBA Stats Data With Python And Pandas | D39: https://www.youtube.com/watch?v=LobWMsz35NM | E39: Basketball (NBA) | F39: https://github.com/dataquestio/project-walkthroughs/blob/master/mvp/predictors.ipynb | H39: part 2
A40: Basketball ML | B40: Machine learning | C40: Predicting the NBA MVP: Machine Learning Project | D40: https://www.youtube.com/watch?v=3cn1nHlbFVw | E40: Basketball (NBA) | F40: https://github.com/dataquestio/project-walkthroughs/blob/master/mvp/machine_learning.ipynb | G40: https://github.com/dataquestio/project-walkthroughs/blob/master/mvp/player_mvp_stats.csv | H40: part 3
A41: YouTube Tutorial | B41: Web scraping | C41: How to scrape NBA data using the nba_api package | D41: https://www.youtube.com/watch?v=NCyPY-jfb3I | E41: Basketball (NBA)
A42: YouTube Tutorial | B42: Scrpaing & Data Viz | C42: Animating NBA Games with matplotlib and pandas | D42: https://www.dunderdata.com/blog/animating-nba-games-with-matplotlib-and-pandas | E42: Basketball (NBA)
A44: Blog tutorial | B44: nflfastR | C44: Using nflfastR in python | D44: https://github.com/maxbolger/nflfastR-Python-Tutorial/blob/main/nflfastR_python_tutorial.ipynb | E44: NFL
A45: NFL data - beginner | B45: Blog series | C45: Learn Python with NFL Data - Next Gen Stats | D45: https://www.fantasyfootballdatapros.com/posts | E45: NFL | H45: part 1
A46: NFL data - intermediate | B46: Blog series | C46: Learn Python with NFL Data - Next Gen Stats | D46: https://www.fantasyfootballdatapros.com/posts | E46: NFL | H46: part 2
A47: NFL data - machine learning | B47: Blog series | C47: Learn Python with NFL Data - Next Gen Stats | D47: https://www.fantasyfootballdatapros.com/posts | E47: NFL | H47: part 3
A48: NFL data - research | B48: Blog series | C48: Learn Python with NFL Data - Next Gen Stats | D48: https://www.fantasyfootballdatapros.com/posts | E48: NFL | H48: part 4
A49: NFL data - fantasy football | B49: Blog series | C49: Learn Python with NFL Data - Next Gen Stats | D49: https://www.fantasyfootballdatapros.com/posts | E49: NFL | H49: part 5
A50: Modeling tutorial | B50: blog tutorial | C50: How to predict NFL winners in python | D50: https://www.activestate.com/blog/how-to-predict-nfl-winners-with-python/ | E50: NFL
A51: nflscrapeR in python | B51: Data viz | C51: Introduction to working with nflscrapR data in Python | D51: https://gist.github.com/Deryck97/fa4abc0e66b77922634be9f51f9a1052 | E51: NFL
A52: Data cleaning & visualization | B52: Data tutorial | C52: NFL Pro Day Data | D52: https://github.com/TheAthleticEthan/nfl_tutorials/blob/main/Pro%20Day%20Exploratory%20Data%20Analysis.ipynb | E52: NFL
A54: Intro to baseball analytics | B54: Data Science | C54: Baseball Analytics Pt. 1 | D54: https://www.datacamp.com/tutorial/scikit-learn-tutorial-baseball-1 | E54: MLB
...

Sheet Py Packages
A1: Python Packages
A3: Website/Package | B3: Description | C3: Link | D3: Sport
A4: PySport open source | B4: One of the BEST resources! Has links to packages in all sports in many languages | C4: https://opensource.pysport.org/ | D4: All sports
A5: Sports dataverse | B5: Open-source sports data package for CBB, CFB, NBA, WNBA, CWBB, NFL, and NHL | C5: https://sportsdataverse-py.sportsdataverse.org/docs/intro | D5: All sports
A6: sportpy | B6: Code necessary to draw scale versions of playing surfaces to visualize play-by-play data | C6: https://sportypy.sportsdataverse.org/ | D6: All sports
A7: teamcolors | B7: Package to pull team colors palettes for pro sports teams | C7: https://github.com/beanumber/teamcolors | D7: All sports
A8: sportsipy | B8: Free python API that pulls the stats from www.sports-reference.com | C8: https://sportsreference.readthedocs.io/en/stable/ | D8: All sports
A9: sportsreference | B9: free python API that pulls the stats from www.sports-reference.com | C9: https://pypi.org/project/sportsreference/ | D9: All sports
A11: mplBasketball | B11: Python plotting library to visualize basketball data, created by the Sport Performance Lab at MLSE | C11: https://github.com/mlsedigital/mplbasketball | D11: Basketball (NBA & WNBA)
A12: py_ball | B12: Python API wrapper for stats.nba.com with a focus on NBA and WNBA applications | C12: https://github.com/basketballrelativity/py_ball | D12: Basketball (NBA & WNBA)
A13: nba_api | B13: An API Client package to access the APIs for NBA.com | C13: https://github.com/swar/nba_api | D13: Basketball (NBA)
A14: nba_data | B14: Dataset NBA play-by-play data and shotdetails from 1996/1997 to 2023/24 | C14: https://github.com/shufinskiy/nba_data | D14: Basketball (NBA)
A15: nba_on_court | B15: Fast download of play-by-play data and adding data about players on court in NBA games | C15: https://github.com/shufinskiy/nba-on-court | D15: Basketball (NBA)
... A47: Hockey_Scraper | B47: Scrape NHL data off the NHL API and website | C47: https://github.com/HarryShomer/Hockey-Scraper | D47: Hockey

Sheet Py Accounts
A1: Python Accounts to Follow
A3: Account @ | B3: Description | C3: Link | D3: Sport
A4: @bballport | B4: Basketball packages and API in python | C4: @bballport | D4: Basketball
A5: @automaticnba | B5: Current event NBA blogging | C5: @automaticnba | D5: Basketball
A6: @py_ball_ | B6: Python packages and data viz | C6: @py_ball_ | D6: Basketball
A7: @anpatt7 | B7: R and Python basketball tutorials - DARKO "frontman" | C7: @anpatt7 | D7: Basketball
A8: @vshufinskiy | B8: Super helpful in posting public datasets! Basketball data viz as well. | C8: @vshufinskiy | D8: Basketball
A9: @Eugenetiwat_ | B9: High-level coder & app developer. CUSE MBB! | C9: @Eugenetiwat_ | D9: Basketball
A10: @jessefischer33 | B10: CBB draft model & data viz. Sports analytics blogger. | C10: @jessefischer33 | D10: Basketball
A11: @GabeLeftBrain | B11: NBA blogger with an icnredible python based bot | C11: @GabeLeftBrain | D11: Basketball
A12: @SravanNBA | B12: Python programmer with NBA blog w/ tutorials | C12: @SravanNBA | D12: Basketball
A13: @vshufinskiy | B13: Python based ML engineer who created nba_data and nba_on_court | C13: @vshufinskiy | D13: Basketball
A15: @mckayjohns | B15: THE BEST youtube python tutorials & data viz (Barcelona) | C15: @mckayjohns | D15: Soccer (football) | E15: https://www.youtube.com/c/McKayJohns/videos
A16: @UtdArena | B16: The goat w/ data viz and all around analysis (Man United) | C16: @UtdArena | D16: Soccer (football)
A17: @markrstats | B17: One of my personal biggest data visualization inspirations on twitter!! | C17: @markrstats | D17: Soccer (football)
A18: @GoalAnalysis | B18: Data visualization & written analysis (Barcelona) | C18: @GoalAnalysis | D18: Soccer (football)
A19: @jonollington | B19: Data visualization (Arsenal) | C19: @jonollington | D19: Soccer (football)
A20: @petermckeever | B20: Data visualization and interactive web apps | C20: @petermckeever | D20: Soccer (football)
A21: @victorrenaud5 | B21: Data visualization | C21: @victorrenaud5 | D21: Soccer (football)
A22: @jdeposicion | B22: Data visualization & written analysis (Barcelona) | C22: @jdeposicion | D22: Soccer (football)
A23: @amonizfootball | B23: Data visualization and player/tactical analysis (Man Utd.) | C23: @amonizfootball | D23: Soccer (football)
A24: @lambertsmarc | B24: Data visualization & written analysis | C24: @lambertsmarc | D24: Soccer (football)
A25: @ArabAnalytics | B25: Data visualization | C25: @ArabAnalytics | D25: Soccer (football)
A26: @Odriozolite | B26: Data visualization & written analysis (Madrid) | C26: @Odriozolite | D26: Soccer (football)
A27: @Soumyaj15209314 | B27: Data visualization & coding examples | C27: @Soumyaj15209314 | D27: Soccer (football)
... A46: @TopDownHockey | B46: Hickey data analysis & blog post tutorials | C46: @TopDownHockey | D46: Hockey
D48: Python Blogger

Sheet Tableau Tutorials
A1: Tableau Tutorials
A3: Subject | B3: Type | C3: Description | D3: Link | E3: Sport (if applicable) | F3: Account | G3: Data
A4: Tableau Installation | B4: Intro | C4: HOW TO DOWNLOAD AND INSTALL TABLEAU | D4: https://www.youtube.com/watch?v=6xv1KvCMF1Q | E4: General
A5: Tableau chart guide | B5: Data Viz | C5: Ultimate cheat sheet on tableau charts | D5: https://towardsdatascience.com/the-ultimate-cheat-sheet-on-tableau-charts-642bca94dde5 | E5: General Data Viz
A7: Getting started | B7: How to Start | C7: Getting Started with Tableau for Sports | D7: https://www.youtube.com/watch?v=BcGRl6PE3Ss&t=876s | E7: Soccer (football) | F7: @thevideoanalyst
A8: Sheets | B8: Data science/viz | C8: How to Merge Multiple Sheets | D8: https://www.youtube.com/watch?v=AgydLKJlQjM | E8: Soccer (football) | F8: @thevideoanalyst
A9: Pass Maps | B9: Data science/viz | C9: Using Tableau Prep to Create Football Pass Maps | D9: https://www.youtube.com/watch?v=AxYnhLeRkhA&t=481s | E9: Soccer (football) | F9: @thevideoanalyst
A10: Mapping XY | B10: Data science/viz | C10: Tableau for Sport Mapping XY Data | D10: https://www.youtube.com/watch?v=Cs8_Fgqy5Oc&t=59s | E10: Soccer (football) | F10: @thevideoanalyst
A11: Dashboards | B11: Data science/viz | C11: Tableau for Sport: Football Scouting Dashboard | D11: https://www.youtube.com/watch?v=-oAfUTqut8o | E11: Soccer (football) | F11: @thevideoanalyst
A12: Pass Maps | B12: Data science/viz | C12: Creating a Football Pass Map in Tableau | D12: https://www.youtube.com/watch?v=o6F9X_Odcu0&t=838s | E12: Soccer (football) | F12: @thevideoanalyst
A13: Timeline Graphs | B13: Data science/viz | C13: Creating a Timeline of Events in Tableau | D13: https://www.youtube.com/watch?v=LRFEHIuUuuI | E13: Soccer (football) | F13: @thevideoanalyst
A14: Data Scraping | B14: Data science/viz | C14: Data Scraping in Tableau (Google Sheets) | D14: https://www.youtube.com/watch?v=8AJWR-YtpHQ | E14: Soccer (football) | F14: @thevideoanalyst
A15: Zonal Pitches | B15: Data science/viz | C15: Using Tableau to Create Zones on a Pitch | D15: https://www.youtube.com/watch?v=PCXtqmloDMI | E15: Soccer (football) | F15: @thevideoanalyst
A16: Beeswarm plots | B16: Data science/viz | C16: Beeswarm Plot - Tableau | D16: https://www.youtube.com/watch?v=Cq3B9czS0Fg | E16: Soccer (football) | F16: @thevideoanalyst
A17: Small multiples | B17: Data science/viz | C17: Tableau Sport Small Multiples | D17: https://www.youtube.com/watch?v=BORcRsto7C8 | E17: Soccer (football) | F17: @thevideoanalyst
A18: Lollipop graphs | B18: Data viz | C18: Introducing Lollipop graphs using dual axis in Tableau | D18: https://www.youtube.com/watch?v=OfdTUtRB0p4 | E18: Soccer (football) | F18: @NinadB_06
... A36: Blog post | B36: Data Viz | C36: How to plot a Basketball Shot Chart using Tableau | D36: https://www.thedataschool.com.au/joshua-verbeek/how-to-plot-a-basketball-shot-chart-using-tableau/ | E36: Basketball (NBA) | F36: https://www.thedataschool.com.au/category/joshua-verbeek/
A38: Conference Talk (Tutorial) | B38: General Talk | C38: Tablea Tutorial - OTTHAC 2019 | D38: https://www.youtube.com/watch?v=9JsY6RHeYT8 | E38: Hockey
A40: Anthony Smoak - YouTube | B40: Data Viz | C40: Stacked Bar Chart Totals in Tableau | D40: https://www.youtube.com/watch?v=CylyFY0UIj0 | E40: General | F40: @AnthonySmoak
A42: Tableau Training | B42: YouTube Video | C42: Tableau Training for Beginners - 8 HOURS for free !!! | D42: https://www.youtube.com/watch?v=KA0QHWm0nWo | E42: Course Video
A43: Tableau Full Course | B43: YouTube Video | C43: Tableau Tutorial for Beginners - 6 HOURS FOR FREE !!! | D43: https://www.youtube.com/watch?v=aHaOIvR00So | E43: Course Video
A44: Tableau Desktop Tutorial | B44: YouTube Video | C44: 4 HOURS of Beginner to Advanced Tableau Training | D44: https://www.youtube.com/watch?v=wFCiKvBgiwg | E44: Course Video
A46: Tableau in Two Minutes | B46: YouTube Video | C46: Tableau Basics for Beginners | D46: https://www.youtube.com/watch?v=jEgVto5QME8 | E46: General
A47: Dashboard Walkthrough | B47: YouTube Video | C47: Design Secrets for a Non-Designer: Modern Business Dashboard | D47: https://www.youtube.com/watch?v=nkIy3ruOmZw | E47: General
A49: Project Walkthrough | B49: YouTube Video | C49: Tableau Dashboard from Start to End (Part 1) | D49: https://www.youtube.com/watch?v=oAIubTqg-Kw | E49: General
A50: Project Walkthrough | B50: YouTube Video | C50: Tableau Dashboard from Start to End (Part 2) | D50: https://www.youtube.com/watch?v=oTyCZVnNVZA | E50: General
A51: Project Walkthrough | B51: YouTube Video | C51: Tableau Dashboard from Start to End (Part 3) | D51: https://www.youtube.com/watch?v=8_eVFXUGebA | E51: General

Sheet Tableau Accounts
A1: Tableau Accounts to Follow
A3: Account @ | B3: Description | C3: Link | D3: Tableau Public | E3: Sport
A4: @eddwebster | B4: Data scientist w/ BEST football analytics guide. Former West Ham and City Group. | C4: @eddwebster | D4: https://public.tableau.com/app/profile/edd.webster | E4: Soccer (football)
A5: @thevideoanalyst | B5: Amazing YouTube tutorials w/ a focus on European football. | C5: @thevideoanalyst | E5: Soccer (football)
A6: @NinadB_06 | B6: Freelance sports journalist. High-level Tableau YouTube tutorials (data viz) | C6: @NinadB_06 | E6: Soccer (football)
A7: @futbolanalysr | C7: @futbolanalysr | E7: Soccer (football)
A8: @_CJMayes | B8: SportsVizSunday curator. Tableau viz and tutorials | C8: @_CJMayes | D8: https://public.tableau.com/app/profile/cj.mayes | E8: Soccer (football)
A9: @Advt_played | B9: Football consultant. Player and team visualizations and dashboards. | C9: @Advt_played | D9: https://public.tableau.com/app/profile/james.vaughan1697#!/ | E9: Soccer (football)
A10: AshwinRaman_ | B10: Football writer, with several Tableau tutorials and countless data articles. | C10: @AshwinRaman_ | D10: https://public.tableau.com/app/profile/ashwin.raman1303 | E10: Soccer (football)
A11: CarlonCarpenter | B11: Football analyst for Statsbomb. Provides an insane amount of public tutorials & guide. | C11: @CarlonCarpenter | D11: https://public.tableau.com/app/profile/carlon.carpenter#!/?newProfile=&activeTab=0 | E11: Soccer (football)
A13: @jgtrends | B13: NBA & CBB datas visualizations. Awesome, timely coontent! | C13: @jgtrends | E13: Basketball
A14: @AnthonySmoak | B14: General Tableau content with periodic basketball examples. | C14: @AnthonySmoak | E14: Basketball
A16: @EpleySamuel | B16: NBA & NFL infographics in tableau. Super informative. | C16: @EpleySamuel | E16: Basketball | F16: NFL
A18: @TopDownHockey | B18: Hockey data viz and analysis (Player cards & projections) | C18: @TopDownHockey | E18: Hockey
A19: @ChartingHockey | B19: Player reports, NHL viz, and tutorials | C19: @ChartingHockey | E19: Hockey
A20: @VizWhat | B20: NHL player dashboards and viz | C20: @VizWhat | E20: Hockey
A21: @ShutdownLine | B21: NHL analytics blogger. | C21: @ShutdownLine | E21: Hockey
A23: @Ali15Tehrani | B23: Data visulizations w/ a focus on all kings of topics | C23: @Ali15Tehrani | E23: General
A24: @RileyData | B24: Tableau data visuailzations in sprots & non-sport topics | C24: @RileyData | E24: General
A25: @JtothaVizzo | B25: Tableau data visualizations & dashboards | C25: @JtothaVizzo | E25: General
A26: @professorkao | C26: @professorkao | E26: General
A27: @Lodhaviz | C27: @Lodhaviz | E27: General
A28: @VizByMoon | C28: @VizByMoon | E28: General

Sheet SQL Tutorials
A1: SQL Tutorials
A3: Subject | B3: Type | C3: Description | D3: Link | E3: Sport (if applicable) | F3: Code | G3: Data
A4: SQL Server Installation | B4: Download | C4: HOW TO DOWNLOAD AND INSTALL SQL SERVER (MAC) | D4: https://www.youtube.com/watch?v=9c7Ti2OcLZg | E4: General
A5: SQL Server Installation | B5: Download | C5: HOW TO DOWNLOAD AND INSTALL SQL SERVER (WINDOWS) | D5: https://www.youtube.com/watch?v=kGdTg-vGs-E | E5: General
A7: SQL Tutorial Video | B7: Video | C7: SQL for Sports Analytics (Lahman's Database) | D7: https://www.playingnumbers.com/2020/01/sql-for-sports-analytics/ | E7: General Guide | F7: Baseball
A9: Blog Exercies | B9: Blog | C9: SQL Exercises, Practice, Solution - Soccer Database | D9: https://www.w3resource.com/sql-exercises/soccer-database-exercise/index.php | E9: Soccer (football)
A10: SQL Q&A Session | B10: YouTube Video | C10: Training Ground Guru -- Edd Webster: SQL Q&A | D10: https://trainingground.guru/articles/edd-webster-sql-q-and-a | E10: Soccer (football)
A11: SQL Server | B11: YouTube Video | C11: Using SQL Server with Football Trading Data | D11: https://www.youtube.com/watch?v=UAis4LD-iF8 | E11: Soccer (football)
A13: SQL Query Tutorial | B13: YouTube Video | C13: Practice Writing SQL Queries using Real Dataset | D13: https://www.youtube.com/watch?v=XruOBp7yPXU | E13: Olympics
A15: Learn Basic SQL in 15 Mins. | B15: Part 1 | C15: Business Intelligence For Beginners | D15: https://www.youtube.com/watch?v=kbKty5ZVKMY | E15: General - Part 1
A16: Learn Basic SQL in 15 Mins. | B16: Part 2 | C16: Creating Tables | D16: https://www.youtube.com/watch?v=gm6tNK_iOHs | E16: General - Part 2
A17: Learn Basic SQL in 15 Mins. | B17: Part 3 | C17: SQL Functions Tutorial | D17: https://www.youtube.com/watch?v=w3ea4fKiS2g | E17: General - Part 3
A19: SQL Tutorial For Beginners | B19: YouTube Video | C19: SQL Full Course - 8 HOURS FOR FREE !!! | D19: https://www.youtube.com/watch?v=AA7i2GcTGwU | E19: General Course
A20: Huge SQL Tutorial | B20: YouTube Video | C20: Full Database Course for Beginners - 4 HOURS FOR FREE !!! | D20: https://www.youtube.com/watch?v=HXV3zeQKqGY | E20: General Course
A21: SQL Tutorial Video | B21: YouTube Video | C21: MySQL Tutorial for Beginners - 3 HOURS FOR FREE !!! | D21: https://www.youtube.com/watch?v=7S_tz1z_5bA | E21: General Course
A22: SQL Tutorial | B22: YouTube Video | C22: SQL Tutorial : SQL Full Course - 2 HOURS FOR FREE !!! | D22: https://www.youtube.com/watch?v=XqIk2PwP0To | E22: General Course
A23: SQL Data Analysis | B23: YouTube Video | C23: Learn SQL for Data Analysis in one hour (sample data + 50 queries) | D23: https://www.youtube.com/watch?v=l8DCPaHc5TQ | E23: General
... A28: Learn SQL: Interactively | B28: Blog Tutorial | C28: DQL Tutorial blog course with interactive code. | D28: https://www.programiz.com/sql | E28: General Blog

Sheet Data Resources
A1: Data Resources
A3: Website/Package | B3: Description | C3: Link | D3: Sport
A4: NBA CSV file | B4: NBA shot location data from the 03-04 season to 23-24 w/ data viz example code. | C4: https://github.com/DomSamangy/NBA_Shots_04_23 | D4: Basketball (NBA)
A5: NBA CSV file | B5: NBA play type data from 2015-16 to the recently completed 2023-24 season. | C5: https://github.com/DomSamangy/NBA_Play_Types_16_23 | D5: Basketball (NBA)
A7: Shot-Plotter | B7: A graphical interface for tracking locational events in sports. HUGE! | C7: https://shot-plotter.netlify.app/ | D7: General
A8: GitHub Repo | B8: Repo to find data for various different sports! | C8: https://github.com/meysubb/Sports_Data_Reference | D8: General
A9: Packages | B9: List of packages useful for sports analytics | C9: https://cran.r-project.org/web/views/SportsAnalytics.html | D9: General
A10: SPL Open Data | B10: Collection of biomechanics datasets collected by MLSE Sport Performance Lab | C10: https://github.com/mlsedigital/SPL-open-data?tab=readme-ov-file | D10: General
A12: NBA University | B12: Twitter page that easily translate data to the mass of NBA fans | C12: https://twitter.com/NBA_University | D12: Basketball (NBA)
A13: website w/ CSV files | B13: Basketball Refence | C13: https://www.basketball-reference.com/ | D13: Basketball (NBA & NCAA)
A14: website | B14: NBA data | C14: https://www.nba.com/stats/players/traditional/?sort=PTS&dir=-1 | D14: Basketball (NBA)
A15: CSV file | B15: NBA Shot Data csv file - (2015-2020) -- EXTENSIVE | C15: https://github.com/DomSamangy/All_NBA_Shots_Data_2015-2020 | D15: Basketball (NBA)
A16: website | B16: PBPstats.com | C16: https://www.pbpstats.com/ | D16: Basketball (NBA)
... A65: website w/ tabs | B65: Rugby stats by varying countries and their competitions | C65: https://www.itsrugby.co.uk/playersearch.html | D65: Rugby

Sheet Cheatsheets
A1: Cheatsheets
A3: Topic | B3: Description | C3: Link
A4: ggplot2 cheatsheet | B4: Data visualization | C4: https://ggplot2.tidyverse.org/ | D4: R
A5: Shiny apps cheatsheet | B5: Bulding apps | C5: https://shiny.posit.co/r/articles/start/cheatsheet/ | D5: R
A6: Tidyverse cheatsheet | B6: Transforming and visualizing data | C6: https://s3.amazonaws.com/assets.datacamp.com/blog_assets/Tidyverse+Cheat+Sheet.pdf | D6: R
A7: Dplyr cheatsheet | B7: Data transformation | C7: https://github.com/rstudio/cheatsheets/blob/master/data-transformation.pdf | D7: R
A8: Tidyr cheatsheet | B8: Data tidying | C8: https://github.com/rstudio/cheatsheets/blob/master/tidyr.pdf | D8: R
A9: Lubridate cheatsheet | B9: Dates and times | C9: https://github.com/rstudio/cheatsheets/blob/master/lubridate.pdf | D9: R
A10: Forcats cheatsheet | B10: Working with factors | C10: https://github.com/rstudio/cheatsheets/blob/master/factors.pdf | D10: R
A11: IDE cheatsheet | B11: Understanding R's working environment | C11: https://github.com/rstudio/cheatsheets/blob/master/rstudio-ide.pdf | D11: R
A12: R Markdown cheatsheet | B12: Understanding r markdown documents | C12: https://github.com/rstudio/cheatsheets/blob/master/rmarkdown.pdf | D12: R
A13: Reticulate cheatsheet | B13: Integrating Python in R through markdown documents | C13: https://github.com/rstudio/cheatsheets/blob/master/reticulate.pdf | D13: R
A14: Readr cheatsheet | B14: Importing data with tidyverse | C14: https://github.com/rstudio/cheatsheets/blob/master/data-import.pdf | D14: R
A15: Purrr cheatsheet | B15: Map functions | C15: https://github.com/rstudio/cheatsheets/blob/master/purrr.pdf | D15: R
... A46: Joins | B46: SQL Joins Cheat Sheet | C46: https://www.datacamp.com/cheat-sheet/sql-joins-cheat-sheet | D46: SQL

Sheet Blogs  Books
A1: Blogs & Books
A3: Blogger // Resource | B3: Description | C3: Link | D3: Type | E3: Sport
A4: Ben Alamar | B4: Sports Analytics: A Guide for Coaches, Managers, and Other Decision Makers | C4: https://www.amazon.com/gp/product/0231162928/ref=as_li_ss_tl?ie=UTF8&linkCode=sl1&tag=nba0b-20&linkId=51ca715a8b24ad6dd7a1d1efd1b9c723&language=en_US | D4: Book | E4: Sport Analytics
A5: Wayne L. Winston | B5: Mathletics: How Gamblers, Managers, and Sports Enthusiasts Use Mathematics in Baseball, Basketball, and Football | C5: https://www.amazon.com/dp/0691177627/ref=cm_sw_r_api_i_90Z88C1XAWQQENAR8BZ0_0 | D5: Book | E5: Sport Analytics
A6: Tobias Moskowitz & Lon Wertheim | B6: Scorecasting: The Hidden Influences Behind How Sports Are Played and Games Are Won | C6: https://www.amazon.com/Scorecasting-Hidden-Influences-Behind-Sports/dp/0307591808 | D6: Book | E6: Sport Analytics
A8: Dean Oliver | B8: Basketball on Paper: Rules and Tools for Performance Analysis | C8: https://www.amazon.com/Basketball-Paper-Rules-Performance-Analysis/dp/1574886886 | D8: Book | E8: Basketball
A9: Seth Partnow | B9: The Midrange Theory | C9: https://www.amazon.com/Midrange-Theory-Seth-Partnow/dp/1629379212 | D9: Book | E9: Basketball
A10: Kirk Goldsberry | B10: Sprawlball: A Visual Tour of the New Era of the NBA | C10: https://www.amazon.com/SprawlBall-Visual-Tour-New-Era/dp/1328767515/ref=sr_1_1?crid=16532JG5OPDCP&keywords=sprawlball+by+kirk+goldsberry&qid=1657035066&s=books&sprefix=sprawl%2Cstripbooks%2C86&sr=1-1 | D10: Book | E10: Basketball
A11: Ben Taylor | B11: Thinking Basketball | C11: https://www.amazon.com/Thinking-Basketball-Ben-Taylor/dp/1532968175/ref=sr_1_1?crid=2GSVH53Q2FSBF&keywords=thinking+basketball&qid=1657035098&s=books&sprefix=thinking+bas%2Cstripbooks%2C83&sr=1-1 | D11: Book | E11: Basketball
A12: Stephen Shea & Christopher Baker | B12: Basketball Analytics: Objective and Efficient Strategies for Understanding How Teams Win | C12: https://www.amazon.com/Basketball-Analytics-Objective-Strategies-Understanding/dp/1492923176/ref=pd_bxgy_img_sccl_2/146-4143009-6449652?pd_rd_w=V1iT5&content-id=amzn1.sym.7757a8b5-874e-4a67-9d85-54ed32f01737&pf_rd_p=7757a8b5-874e-4a67-9d85-54ed32f01737&pf_rd_r=FHG1BXDS2W2J8ETKV271&pd_rd_wg=1fB77&pd_rd_r=b9bd9252-d5e3-4783-aef8-0f4a0f65ea7a&pd_rd_i=1492923176&psc=1 | D12: Book | E12: Basketball
A13: Stephen Shea | B13: Basketball Analytics: Spatial Tracking | C13: https://www.amazon.com/Basketball-Analytics-Tracking-Stephen-Shea/dp/1503236277/ref=asc_df_1503236277/?tag=hyprod-20&linkCode=df0&hvadid=312149988622&hvpos=&hvnetw=g&hvrand=1961174661333391974&hvpone=&hvptwo=&hvqmt=&hvdev=c&hvdvcmdl=&hvlocint=&hvlocphy=1013219&hvtargid=pla-491248676302&psc=1 | D13: Book | E13: Basketball
A15: David Sumpter | B15: Soccermatics: Mathematical Adventures in the Beautiful Game Pro-Edition | C15: https://www.amazon.co.uk/Soccermatics-Mathematical-Adventures-Pro-Bloomsbury/dp/1472924142/ref=tmm_pap_swatch_0?_encoding=UTF8&qid=&sr= | D15: Book | E15: Soccer (football)
A16: Christoph Biermann | B16: Football Hackers: The Science and Art of a Data Revolution | C16: https://www.amazon.com/Football-Hackers-Science-Data-Revolution-ebook/dp/B07NQM3YGK | D16: Book | E16: Soccer (football)
... A19: Simon Kuper | B19: Soccernomics | C19: https://www.amazon.com/Soccernomics-England-Germany-Australia-Destined/dp/1568584814 | D19: Book | E19: Soccer (football)
A20: Sonofacorner | C20: https://www.sonofacorner.com/ | D20: Blog | E20: Soccer (football)
A21: Ryan O'Hanlon | B21: Net Gains: Inside the Beautiful Game’s Analytics Revolution | C21: https://www.amazon.com/Net-Gains-Beautiful-Analytics-Revolution/dp/1419758918 | D21: Book | E21: Soccer (football)
A23: Michael Lewis | B23: Moneyball: The Art of Winning an Unfair Game | C23: https://www.amazon.com/Moneyball-Art-Winning-Unfair-Game/dp/0393324818/ref=sr_1_1?crid=3NS3XZXNPKZDL&keywords=moneyball&qid=1657035924&s=books&sprefix=moneyball%2Cstripbooks%2C91&sr=1-1 | D23: Book | E23: MLB
A24: Tom Tango, Mitchel Lichtman, Andrew Dolphin | B24: The Book: Playing The Percentages In Baseball | C24: https://www.amazon.com/Book-Playing-Percentages-Baseball/dp/1494260174 | D24: Book | E24: MLB
A26: Bob Carroll, Pete Palmer, John Thorn | B26: The Hidden Game of Football | C26: https://www.amazon.com/Hidden-Game-Football-Bob-Carroll/dp/0446514144 | D26: Book | E26: NFL
A28: David Pleuler (Toronto FC) | B28: Amazing soccer analytics handook w/ python focus | C28: https://github.com/devinpleuler/analytics-handbook | D28: Resource/Guide | F28: Python
A29: Edd Webster | B29: Absolutely massive github guide to everything sports analytics | C29: https://github.com/eddwebster/football_analytics | D29: Resource/Guide | F29: General
A30: Andrew Weatherman | B30: Blog w/ visualization turoials with full scource code | C30: https://www.bucketsandbytes.com/ | D30: Blog | E30: Basketball | F30: R
A31: Sravan Pannala | B31: NBA blog with a mutltidue of tutorials and research pieces | C31: https://blog.sradjoker.cc/archive/ | D31: Blog | E31: Basketball | F31: Python
A32: Mckay Johns | B32: Python based newsletter on breaking into sprots analytics | C32: https://mckayjohns.substack.com/ | D32: Blog | E32: Soccer (football) | F32: Python
A33: Thomas Mock | B33: An R-focused blog with awesome tutorials on pretty much everything | C33: https://themockup.blog/ | D33: Blog | F33: R
A34: Owen Phillips | B34: An amazing weekly NBA newsletter full of insight & code examples | C34: https://thef5.substack.com/ | D34: Blog | E34: Basketball | F34: R
A35: Tony Elhabr | B35: Python based blog showcasing current events w/ available code. | C35: https://tonyelhabr.rbind.io/posts | D35: Blog | E35: Soccer (football) | F35: R
A36: Sonofacorner | C36: https://www.sonofacorner.com/ | D36: Blog | E36: Soccer (football) | F36: Python
A37: Sports Viz Sunday | B37: Weekly blog post rounding up the best sports visualizations. | C37: https://www.sportsvizsunday.com/ | D37: Blog | F37: General
A38: Meghan Hall | B38: Blog covering mostly hockey, but also R tutorials | C38: https://meghan.rbind.io/blog/ | D38: Blog | F38: R
A39: Ismael Gómez Schmidt | B39: Personal portfolio that serves as blog showcasing soccer analytics projects | C39: https://www.datofutbol.cl/about/ | D39: Blog | F39: R
A40: R Weekly | B40: Weekly updates from the R community | C40: https://rweekly.org/#get- | D40: Blog | F40: R
A41: Ryan Miele | B41: Data science approach to studying sports | C41: https://medium.com/@ryancmiele | D41: Blog | F41: R
A42: Donald Cayton | B42: Game Models Football | C42: https://www.gamemodelsfootball.com/articles | D42: Blog | E42: Soccer (football) | F42: Python
B43: Don't Blame the Data | C43: https://www.dontblamethedata.com/blog/extract-data-using-worldfootballR/ | D43: Blog | E43: Soccer (football) | F43: R
A44: Corsi Chronicles | B44: In-depth insights, stay updated on the latest hockey developments | C44: https://corsichronicles.substack.com/ | D44: Blog | E44: Hockey
A46: Team Color Codes | B46: Hex, RGB, CMYK, and HSB color codes for any sports team | C46: https://teamcolorcodes.com/ | D46: Resource
A47: Shot-Plotter | B47: A graphical interface for tracking locational events in sports. | C47: https://shot-plotter.netlify.app/basketball-ncaa | D47: Resource/Tool
A48: Soccer Event Tracker | B48: Manual event tracker to creaete your own x,y match data | C48: https://torvaney.github.io/projects/tracker# | D48: Resource/Tool
A49: NBA Injury Report R Scraper | B49: R code to scrape NBA's official daily injury repory(via: @Jake Flancer) | C49: https://www.dropbox.com/sh/ir9md13q45n1r91/AACI27qsiYJt0j3UQL3eaDpea?dl=0 | D49: Scrape | F49: R
...

Sheet Articles
A1: Articles
A3: Source | B3: Title | C3: Link | D3: Sport | E3: Type
A5: The Brunswick News | B5: "Meet the 25-year-old data analyst who’s helping coach the Warriors’ Summer League team" | C5: https://thebrunswicknews.com/sports/national_sports/meet-the-25-year-old-data-analyst-who-s-helping-coach-the-warriors-summer-league/article_9bfcc19c-b65e-5c7e-a45b-13f4976fdf9a.html | D5: Basketball | E5: Experience
A6: Harvard Magazine | B6: "Harvard Graduate Leads in NBA Analytics" | C6: https://www.harvardmagazine.com/2021/06/jhj-sports-rosenfeld | D6: Basketball | E6: Experience
A7: Basketball News (Mat Issa) | B7: "Blazing the Trail: Shane Battier, the data-ball defender" | C7: https://www.basketballnews.com/stories/nba-blazing-the-trail-shane-battier-the-databall-defender-memphis-grizzlies-houston-rockets-miami-heat-daryl-morey-david-fizdale-detroit-pistons-draymond-green | D7: Basketball | E7: Experience
A8: Bleacher Report (Jonathan Wasserman) | B8: "Unmasking the Forefathers of Advanced NBA Stats" | C8: https://bleacherreport.com/articles/1728780-unmasking-the-forefathers-of-advanced-nba-stats | D8: Basketball | E8: Experience
A9: SB Nation (Tim Cato) | B9: "How the Rockets made the wildest scheme in basketball analytics work" | C9: https://www.sbnation.com/2017/4/13/15257614/houston-rockets-stats-winning-james-harden-daryl-morey | D9: Basketball | E9: Experience
A10: Jared Chavez | B10: "How the Indiana Pacers and Fever are revolutionizing Basketball with the Databricks Data Intelligence Platform" | C10: https://www.linkedin.com/pulse/transforming-sports-data-databricks-jared-chavez-xgooc/ | D10: Basketball | E10: Experience
A11: The New Yorker (Isaac Shotiner) | B11: "Jalen Rose Has a Problem with Basketball Analytics" | C11: https://www.newyorker.com/news/q-and-a/jalen-rose-has-a-problem-with-basketball-analytics | D11: Basketball | E11: Experience
A13: The Athletic (Liam Twomey) | B13: "How data and analytics work at Chelsea from top to bottom" | C13: https://www.nytimes.com/athletic/1951313/2020/08/04/chelsea-analytics-data-gps/ | D13: Soccer (football) | E13: Experience
A14: New York Times | B14: "How Data (and Some Breathtaking Soccer) Brought Liverpool to the Cusp of Glory" | C14: https://www.nytimes.com/2019/05/22/magazine/soccer-data-liverpool.html | D14: Soccer (football) | E14: Experience
A15: analyisport | B15: "“What Can Data Do for a Football Club?” A Case Study of Brentford F.C." | C15: https://analyisport.com/insights/what-can-data-do-for-a-football-club/ | D15: Soccer (football) | E15: Experience
A16: The Athletic (Gregg Evans) | B16: "Kevin De Bruyne and the rise of data and analytics in contract negotiations" | C16: https://www.nytimes.com/athletic/5166636/2024/01/03/football-contract-negotiation-data-analytics-transfers/ | D16: Soccer (football) | E16: Experience
... A35: Cranjis McBasketball | B35: "How to understand Synergy play type categories" | C35: https://fansided.com/2017/09/08/nylon-calculus-understanding-synergy-play-type-data/ | D35: NBA | E35: Tutorial
A36: Dylan Murphy | B36: The Basketball Dictionary | C36: https://medium.com/the-basketball-dictionary/the-basketball-dictionary-5c3835e9fe58 | D36: NBA
A37: Mahima Phalkey | B37: "7 Ways NBA Teams Use Analytics for Performance Improvement" | C37: https://www.almabetter.com/bytes/articles/how-nba-teams-use-data-analytics-to-improve-their-performance | D37: NBA
A38: The Guardian | B38: "An exciting next few years’: will Hawk-Eye spark an NBA data revolution? | C38: https://www.theguardian.com/sport/2023/oct/20/nba-hawkeye-data-analytics-insights | D38: NBA
A39: Colin Maher (No Trade Clause) | B39: Offseason Analysis: Comparing Free Agent Contract to Statistical Production (Bigs) | C39: https://notradeclause.com/offseason-analysis-comparing-free-agent-contract-to-statistical-production-bigs/ | D39: NBA
A40: Krishna Narsu | B40: Nylon Calculus: When can we trust a team’s stats? | C40: https://fansided.com/2017/12/21/nylon-calculus-team-stats-noise-stabilization-thunder/ | D40: NBA
A42: Manchester City | B42: "SAP Data Analytics Helps Measure how Football is Changing Lives" | C42: https://www.mancity.com/news/club/manchester-city-cityzens-giving-sap-data-analytics-63756833 | D42: Soccer (football)
A43: 538 (John Muller) | B43: "Possession Is The Puzzle Of Soccer Analytics. These Models Are Trying To Solve It" | C43: https://fivethirtyeight.com/features/possession-is-the-puzzle-of-soccer-analytics-these-models-are-trying-to-solve-it/ | D43: Soccer (football)
A44: The Athletic | B44: "How do people working in football watch football?" | C44: https://www.nytimes.com/athletic/5698185/2024/08/27/how-do-people-working-in-football-watch-football/ | D44: Soccer (football)
A45: Donald Cayton | B45: "Comparing Methods of Rating Players" | C45: https://www.gamemodelsfootball.com/articles/gen2 | D45: Soccer (football)
A46: The Athletic (Michael Cox) | B46: "Has the impact of analytics on modern football been overstated?" | C46: https://www.nytimes.com/athletic/5756088/2024/09/11/how-has-data-changed-football/ | D46: Soccer (football)
A48: Syracuse University Blog | B48: "Sabermetrics: Baseball Analytics and the Science of Winning" | C48: https://onlinegrad.syracuse.edu/blog/sabermetrics-baseball-analytics-the-science-of-winning/ | D48: MLB
A49: USA Today (Gabe Lacques) | B49: "'Moneyball' at 20: Hits, misses, consequences of baseball's most disruptive book" | C49: https://www.usatoday.com/story/sports/mlb/columnist/gabe-lacques/2023/06/28/moneyball-turns-20-book-changed-industry-athletics/70363392007/ | D49: MLB
... A56: WBS Penguins | B56: "The Impact of Analytics on Modern Ice Hockey: How Data is Changing the Game" | C56: https://www.wbspenguins.com/blog/the-impact-of-analytics-on-modern-ice-hockey-how-data-is-changing-the-game/ | D56: Hockey

Sheet Research Papers
A1: Research Papers
A3: Author(s) | B3: Description | C3: Link | D3: Conference | E3: Sport
A4: Dominic Samangy | B4: Under The Radar: An NBA/NCAA Player & Prospect Similarity Model | C4: https://dsamangy.wixsite.com/statsscout/post/under-the-radar-an-nba-ncaa-player-prospect-similarity-model-utilizing-a-factor-analysis-radar | D4: N/A | E4: Basketball
A5: Dominic Samangy | B5: A K-Means Clustering Approach to NBA Draft Big Boards | C5: https://dsamangy.wixsite.com/statsscout/post/a-k-means-clustering-approach-to-nba-draft-big-boards | D5: N/A | E5: Basketball
A6: Tobias Berger, Frank Daumann | B6: Increasing the shot at a quality draft-decision – A Bayesian approach to improve predicting three-point accuracy translation in the NBA Draft | C6: https://global-uploads.webflow.com/5f1af76ed86d6771ad48324b/607a44e7e6616e061a1b8dd4_TobiasBerger-NBAshotquality-RPpaper.pdf | D6: Sloan 2021 | E6: Basketball
A7: Jonathan Bosch, Samuel Kalman | B7: NBA Lineup Analysis on Clustered Player Tendencies: A new approach to the positions of basketball & modeling lineup efficiency of soft lineup aggregates | C7: https://global-uploads.webflow.com/5f1af76ed86d6771ad48324b/5f6a65517f9440891b8e35d0_Kalman_NBA_Line_up_Analysis.pdf | D7: Sloan 2020 | E7: Basketball
A8: Neil Johnson | B8: Extracting Player Tracking Data from Video Using NonStationary Cameras and a Combination of Computer Vision Techniques | C8: https://global-uploads.webflow.com/5f1af76ed86d6771ad48324b/5f6a64711514cb41b91b37d5_Johnson_extracting_player_tracking_data-compressed.pdf | D8: Sloan 2020 | E8: Basketball
A9: Paul Ibrahim | B9: Comparing Free-Throw Forms Among NBA Players Through 3D Similarity Measures | C9: https://www.stat.cmu.edu/cmsac/conference/2020/assets/pdf/Ibrahim.pdf | D9: SMSAC 2020 | E9: Basketball
A10: Akhil Nistala, John Guttag | B10: Using Deep Learning to Understand Patterns of Player Movement in the NBA | C10: https://global-uploads.webflow.com/5f1af76ed86d6771ad48324b/5f6d397254f18b69c3411918_Using-Deep-Learning-to-Understand-Patterns-of-Player-Movement-in-the-NBA.pdf | D10: Sloan 2019 | E10: Basketball
A11: Benjamin T. Foster and Michael D. Binns | B11: Analytics for the Front Office: Valuing Protections on NBA Draft Picks | C11: https://global-uploads.webflow.com/5f1af76ed86d6771ad48324b/5f6d3809f51633165fdb99d2_ValuingProtectionsonNBADraftPicks_Sloan_2_18_2019.pdf | D11: Sloan 2019 | E11: Basketball
A12: Jacob Mortensen, Luke Bornn | B12: From Markov models to Poisson point processes: Modeling movement in the NBA | C12: https://global-uploads.webflow.com/5f1af76ed86d6771ad48324b/5f6d347436e92e64d83f4ff4_Markov-Models-1.pdf | D12: Sloan 2019 | E12: Basketball
A13: Jonathan Bosch | B13: Estimating (Four) Factor Values in the NBA: A Seemingly Unrelated Regression Analysis | C13: https://nessis.org/nessis19/Jonathan-Bosch-poster.pdf | D13: Nessis 2019 | E13: Basketball
A14: Matthew van Bommel | B14: Home Sweet Home: Quantifying Home Court Advantages For NCAA Basketball Statistics | C14: https://nessis.org/nessis19/Matthew-van-Bommel-poster.pdf | D14: Nessis 2019 | E14: Basketball
... A47: Brian Macdonald, Michael Peterson, James Cifu | B47: Using Data Analysis to Predict Attendance for NHL Regular Season Games | C47: https://nessis.org/nessis17/Macdonald.pdf | D47: Nessis 2017 | E47: Hockey

Sheet Shiny Apps
A1: R Shiny Apps
A3: Account | B3: Description | C3: Link | D3: Sport
A4: @DSamangy | B4: 2022 NBA Draft App | C4: https://dsamangy.shinyapps.io/2022_NBA_Draft_App/ | D4: Basketball (NBA & NCAA)
A5: @DSamangy | B5: NBA & NCAA Player Comparison w/ Similariity Scores // 2021 NBA Draft Consesus Board & Player Data | C5: https://dsamangy.shinyapps.io/NBA_NCAA_Similarity_Comps/ | D5: Basketball (NBA & NCAA)
A6: @DSamangy | B6: Premier League Player Comparison w/ Similariity Scores | C6: https://dsamangy.shinyapps.io/Prem_App_2021/?_ga=2.138468603.933234254.1618455143-707439350.1610067091 | D6: Soccer (football)
A8: Jose Fernandez | B8: A minimal app to visualize Expected Possession Value (EPV) in the NBA. | C8: https://josedv.shinyapps.io/EPV_NBA_Dashboard/ | D8: Basketball (NBA)
A9: BBall Index Website | B9: Website landing page. See "free data" tab for extensive shiny apps for NBA data! | C9: https://www.bball-index.com/ | D9: Basketball (NBA)
A10: @CrumpledJumper | B10: NBA Similar Lineups Finder | C10: https://crumpledpaperjumper.shinyapps.io/PassTo3PAWithBox/ | D10: Basketball (NBA)
A11: @CrumpledJumper | B11: More Kick-Out Tracing | C11: https://crumpledpaperjumper.shinyapps.io/PassTo3PAWithBox/ | D11: Basketball (NBA)
A12: @CrumpledJumper | B12: NBA Self-created shot tracker | C12: https://crumpledpaperjumper.shinyapps.io/StarTracks/ | D12: Basketball (NBA)
A13: @CrumpledJumper | B13: Identifying weak links in lineups | C13: https://crumpledpaperjumper.shinyapps.io/WeakLinks/ | D13: Basketball (NBA)
A14: @burakcankoc | B14: NBA Player's Playtype Exploration | C14: https://burakcankoc.shinyapps.io/PlaytypeBreakdown/… | D14: Basketball (NBA)
A15: @cjmarchesani // @gabbyherreralim // @KornHoops | B15: Lockdown Basketball: Better Big Board 2021 | C15: http://lockdownbball.online/better-big-board/ | D15: Basketball (NBA & NCAA)
A16: @gabbyherreralim | B16: Lockdown Basketball: Team Comps | C16: http://lockdownbball.online/team-comps/
A17: @Peter_Zanca | B17: Shot Making vs. Shot Quality | C17: https://pzanca.shinyapps.io/shot-quality-app/ | D17: Basketball (NBA)
A18: @Peter_Zanca | B18: How To Optimize Your NBA Watch Schedule | C18: https://pzanca.shinyapps.io/league_pass_schedule_maker/ | D18: Basketball (NBA)
A19: @kmedved // @anpatt7 | B19: DARKO model to project trajectories of both players and teams | C19: https://apanalytics.shinyapps.io/DARKO/ | D19: Basketball (NBA)
